Workbook

Sheet A股港股
B1: 频率 | C1: 代码 | D1: 单位 | E1: 当前数据 | F1: 数据日期 | G1: 变化 | H1: 上期数据 | I1: 上期日期 | J1: 趋势图
A2: 上证指数 | B2: 日度 | C2: 000001.SH | D2: 点 | E2: =IFERROR(LOOKUP(9.99E+307,指数走势!$F$7:$IM$7),"") -> 4043.6432 | F2: =IFERROR(LOOKUP(2,1/(指数走势!$F$7:$IM$7<>""),指数走势!$F$1:$IM$1),"") -> 46206 | G2: =IFERROR(E2-H2,"") -> 14.7394 | H2: =IFERROR(LOOKUP(9.99E+307,OFFSET(指数走势!$F$7,0,0,1,LOOKUP(2,1/(指数走势!$F$7:$IM$7<>""),COLUMN(指数走势!$F$7:$IM$7))-COLUMN(指数走势!$F$7))),"") -> 4028.9038 | I2: =IFERROR(LOOKUP(2,1/(指数走势!$F$7:$IM$7<>"")/(指数走势!$F$1:$IM$1<F2),指数走势!$F$1:$IM$1),"") -> 46205
A3: 深成指数 | B3: 日度 | C3: 399001.SZ | D3: 点 | E3: =IFERROR(LOOKUP(9.99E+307,指数走势!$F$5:$IM$5),"") -> 15597.512 | F3: =IFERROR(LOOKUP(2,1/(指数走势!$F$5:$IM$5<>""),指数走势!$F$1:$IM$1),"") -> 46206 | G3: =IFERROR(E3-H3,"") -> 98.7015 | H3: =IFERROR(LOOKUP(9.99E+307,OFFSET(指数走势!$F$5,0,0,1,LOOKUP(2,1/(指数走势!$F$5:$IM$5<>""),COLUMN(指数走势!$F$5:$IM$5))-COLUMN(指数走势!$F$5))),"") -> 15498.81 | I3: =IFERROR(LOOKUP(2,1/(指数走势!$F$5:$IM$5<>"")/(指数走势!$F$1:$IM$1<F3),指数走势!$F$1:$IM$1),"") -> 46205
A4: 沪深300 | B4: 日度 | C4: 000300.SH | D4: 点 | E4: =IFERROR(LOOKUP(9.99E+307,指数走势!$F$6:$IM$6),"") -> 4842.1737 | F4: =IFERROR(LOOKUP(2,1/(指数走势!$F$6:$IM$6<>""),指数走势!$F$1:$IM$1),"") -> 46206 | G4: =IFERROR(E4-H4,"") -> 29.878 | H4: =IFERROR(LOOKUP(9.99E+307,OFFSET(指数走势!$F$6,0,0,1,LOOKUP(2,1/(指数走势!$F$6:$IM$6<>""),COLUMN(指数走势!$F$6:$IM$6))-COLUMN(指数走势!$F$6))),"") -> 4812.2957 | I4: =IFERROR(LOOKUP(2,1/(指数走势!$F$6:$IM$6<>"")/(指数走势!$F$1:$IM$1<F4),指数走势!$F$1:$IM$1),"") -> 46205
A5: 创业板指 | B5: 日度 | C5: 399006.SZ | D5: 点 | E5: =IFERROR(LOOKUP(9.99E+307,指数走势!$F$4:$IM$4),"") -> 4019.9341 | F5: =IFERROR(LOOKUP(2,1/(指数走势!$F$4:$IM$4<>""),指数走势!$F$1:$IM$1),"") -> 46206 | G5: =IFERROR(E5-H5,"") -> 2.6606 | H5: =IFERROR(LOOKUP(9.99E+307,OFFSET(指数走势!$F$4,0,0,1,LOOKUP(2,1/(指数走势!$F$4:$IM$4<>""),COLUMN(指数走势!$F$4:$IM$4))-COLUMN(指数走势!$F$4))),"") -> 4017.2735 | I5: =IFERROR(LOOKUP(2,1/(指数走势!$F$4:$IM$4<>"")/(指数走势!$F$1:$IM$1<F5),指数走势!$F$1:$IM$1),"") -> 46205
A6: 北向资金成交额 | B6: 日度 | D6: 亿元 | E6: =IFERROR(IF(A股成交额换手率测试1!I8<>"",A股成交额换手率测试1!I8+A股成交额换手率测试1!L8,A股成交额换手率测试1!I9+A股成交额换手率测试1!L9),"") -> 3915.1525 | F6: =IF(A股成交额换手率测试1!I8<>"",A股成交额换手率测试1!H8,A股成交额换手率测试1!H9) -> 46206 | G6: =IFERROR(E6-H6,"") -> -325.028 | H6: =IFERROR(IF(A股成交额换手率测试1!I8<>"",A股成交额换手率测试1!I9+A股成交额换手率测试1!L9,A股成交额换手率测试1!I10+A股成交额换手率测试1!L10),"") -> 4240.1805 | I6: =IF(A股成交额换手率测试1!I8<>"",A股成交额换手率测试1!H9,A股成交额换手率测试1!H10) -> 46205
A7: A股日度成交额 | B7: 日度 | D7: 亿元 | E7: =IFERROR(A股成交额换手率测试1!B9,"") -> 32052.617 | F7: =A股成交额换手率测试1!A9 -> 2026-07-03 | G7: =IFERROR(E7-H7,"") -> -2686.6458 | H7: =IFERROR(A股成交额换手率测试1!B10,"") -> 34739.263 | I7: =A股成交额换手率测试1!A10 -> 2026-07-02
A8: 融资融券余额 | B8: 日度 | D8: 万亿元 | E8: =IFERROR(A股成交额换手率测试1!F9/1000000000000,"") -> 3.0033369 | F8: =A股成交额换手率测试1!E9 -> 46206 | G8: =IFERROR(E8-H8,"") -> -0.019559298 | H8: =IFERROR(A股成交额换手率测试1!F10/1000000000000,"") -> 3.0228962 | I8: =A股成交额换手率测试1!E10 -> 46205
A9: 市场换手率 | B9: 日度 | D9: % | E9: =IFERROR(A股成交额换手率测试1!C9,"") -> 3.8454036 | F9: =A股成交额换手率测试1!A9 -> 2026-07-03 | G9: =IFERROR(E9-H9,"") -> -0.17865275 | H9: =IFERROR(A股成交额换手率测试1!C10,"") -> 4.0240564 | I9: =A股成交额换手率测试1!A10 -> 2026-07-02
A10: 恒生指数 | B10: 日度 | C10: HSI.HI | D10: 点 | E10: =IFERROR(LOOKUP(9.99E+307,指数走势!$F$8:$IM$8),"") -> 23350.03 | F10: =IFERROR(LOOKUP(2,1/(指数走势!$F$8:$IM$8<>""),指数走势!$F$1:$IM$1),"") -> 46206 | G10: =IFERROR(E10-H10,"") -> 295 | H10: =IFERROR(LOOKUP(9.99E+307,OFFSET(指数走势!$F$8,0,0,1,LOOKUP(2,1/(指数走势!$F$8:$IM$8<>""),COLUMN(指数走势!$F$8:$IM$8))-COLUMN(指数走势!$F$8))),"") -> 23055.03 | I10: =IFERROR(LOOKUP(2,1/(指数走势!$F$8:$IM$8<>"")/(指数走势!$F$1:$IM$1<F10),指数走势!$F$1:$IM$1),"") -> 46205
A11: 恒生科技指数 | B11: 日度 | C11: HSTECH.HI | D11: 点 | E11: =IFERROR(LOOKUP(9.99E+307,指数走势!$F$3:$IM$3),"") -> 4499 | F11: =IFERROR(LOOKUP(2,1/(指数走势!$F$3:$IM$3<>""),指数走势!$F$1:$IM$1),"") -> 46206 | G11: =IFERROR(E11-H11,"") -> 44.72 | H11: =IFERROR(LOOKUP(9.99E+307,OFFSET(指数走势!$F$3,0,0,1,LOOKUP(2,1/(指数走势!$F$3:$IM$3<>""),COLUMN(指数走势!$F$3:$IM$3))-COLUMN(指数走势!$F$3))),"") -> 4454.28 | I11: =IFERROR(LOOKUP(2,1/(指数走势!$F$3:$IM$3<>"")/(指数走势!$F$1:$IM$1<F11),指数走势!$F$1:$IM$1),"") -> 46205
A12: 南向资金净流入 | B12: 日度 | D12: 亿元 | E12: =IFERROR(A股成交额换手率测试1!P8+A股成交额换手率测试1!S8,"") -> 39.264 | F12: =A股成交额换手率测试1!O8 -> 46206 | G12: =IFERROR(E12-H12,"") -> 56.3312 | H12: =IFERROR(A股成交额换手率测试1!P9+A股成交额换手率测试1!S9,"") -> -17.0672 | I12: =A股成交额换手率测试1!O9 -> 46205
A13: 港股换手率 | B13: 日度 | D13: % | E13: =IFERROR(LOOKUP(9.99E+307,指数走势!$F$17:$IM$17),"") -> 0.32 | F13: =IFERROR(LOOKUP(2,1/(指数走势!$F$17:$IM$17<>""),指数走势!$F$1:$IM$1),"") -> 46206 | G13: =IFERROR(E13-H13,"") -> -0.0707 | H13: =IFERROR(LOOKUP(9.99E+307,OFFSET(指数走势!$F$17,0,0,1,LOOKUP(2,1/(指数走势!$F$17:$IM$17<>""),COLUMN(指数走势!$F$17:$IM$17))-COLUMN(指数走势!$F$17))),"") -> 0.3907 | I13: =IFERROR(LOOKUP(2,1/(指数走势!$F$17:$IM$17<>"")/(指数走势!$F$1:$IM$1<F13),指数走势!$F$1:$IM$1),"") -> 46205
A14: 港股成交额 | B14: 日度 | C14: G8324453 | D14: 亿 | E14: =IFERROR(LOOKUP(9.99E+307,宏观数据!$F$112:$UN$112)/100,"") -> 3049.54 | F14: =IFERROR(LOOKUP(2,1/(宏观数据!$F$112:$UN$112<>""),宏观数据!$F$1:$UN$1),"") -> 46206 | G14: =IFERROR(E14-H14,"") -> -646.79 | H14: =IFERROR(LOOKUP(9.99E+307,OFFSET(宏观数据!$F$112,0,0,1,LOOKUP(2,1/(宏观数据!$F$112:$UN$112<>""),COLUMN(宏观数据!$F$112:$UN$112))-COLUMN(宏观数据!$F$112)))/100,"") -> 3696.33 | I14: =IFERROR(LOOKUP(2,1/(宏观数据!$F$112:$UN$112<>"")/(宏观数据!$F$1:$UN$1<F14),宏观数据!$F$1:$UN$1),"") -> 46205
A15: 上证所:股票账户新开户数:个人:当月值 | B15: 月度 | C15: F5536637 | E15: =IFERROR(LOOKUP(9.99E+307,宏观数据!$F$86:$UN$86),"") -> 285.2384 | F15: =IFERROR(LOOKUP(2,1/(宏观数据!$F$86:$UN$86<>""),宏观数据!$F$1:$UN$1),"") -> 46203 | G15: =IFERROR(E15-H15,"") -> 9.6554 | H15: =IFERROR(LOOKUP(9.99E+307,OFFSET(宏观数据!$F$86,0,0,1,LOOKUP(2,1/(宏观数据!$F$86:$UN$86<>""),COLUMN(宏观数据!$F$86:$UN$86))-COLUMN(宏观数据!$F$86))),"") -> 275.583 | I15: =IFERROR(LOOKUP(2,1/(宏观数据!$F$86:$UN$86<>"")/(宏观数据!$F$1:$UN$1<F15),宏观数据!$F$1:$UN$1),"") -> 46173
A16: 上证沪港通AH溢价指数 | B16: 日度 | C16: H50066.CSI | D16: 点 | E16: =IFERROR(LOOKUP(9.99E+307,指数走势!$F$9:$IM$9),"") -> 132.836 | F16: =IFERROR(LOOKUP(2,1/(指数走势!$F$9:$IM$9<>""),指数走势!$F$1:$IM$1),"") -> 46206 | G16: =IFERROR(E16-H16,"") -> -0.406 | H16: =IFERROR(LOOKUP(9.99E+307,OFFSET(指数走势!$F$9,0,0,1,LOOKUP(2,1/(指数走势!$F$9:$IM$9<>""),COLUMN(指数走势!$F$9:$IM$9))-COLUMN(指数走势!$F$9))),"") -> 133.242 | I16: =IFERROR(LOOKUP(2,1/(指数走势!$F$9:$IM$9<>"")/(指数走势!$F$1:$IM$1<F16),指数走势!$F$1:$IM$1),"") -> 46205
A17: ETF净流入 | B17: 日度 | C17: ETF市场申赎净流入 | D17: 亿元 | E17: =IFERROR(LOOKUP(2,1/(A股成交额换手率测试1!$AD$7:$AD$400<>""),A股成交额换手率测试1!$AD$7:$AD$400)/100000000,"") -> -81.442033 | F17: =IFERROR(LOOKUP(2,1/(A股成交额换手率测试1!$AD$7:$AD$400<>""),A股成交额换手率测试1!$AC$7:$AC$400),"") -> 46206 | G17: =IFERROR(E17-H17,"") -> -370.19565 | H17: =IFERROR(LOOKUP(2,1/(A股成交额换手率测试1!$AD$7:$AD$400<>"")/(ROW(A股成交额换手率测试1!$AD$7:$AD$400)<LOOKUP(2,1/(A股成交额换手率测试1!$AD$7:$AD$400<>""),ROW(A股成交额换手率测试1!$AD$7:$AD$400))),A股成交额换手率测试1!$AD$7:$AD$400)/100000000,"") -> 288.75362 | I17: =IFERROR(LOOKUP(2,1/(A股成交额换手率测试1!$AD$7:$AD$400<>"")/(ROW(A股成交额换手率测试1!$AD$7:$AD$400)<LOOKUP(2,1/(A股成交额换手率测试1!$AD$7:$AD$400<>""),ROW(A股成交额换手率测试1!$AD$7:$AD$400))),A股成交额换手率测试1!$AC$7:$AC$400),"") -> 46205
A18: 上证指数PE(TTM) | B18: 日度 | C18: 000001.SH | D18: 倍 | E18: =IFERROR(LOOKUP(2,1/(指数走势!$F$32:$ACK$32<=$F$2)/(指数走势!$F$33:$ACK$33<>""),指数走势!$F$33:$ACK$33),"") -> 16.941 | F18: =IFERROR(LOOKUP(2,1/(指数走势!$F$32:$ACK$32<=$F$2)/(指数走势!$F$33:$ACK$33<>""),指数走势!$F$32:$ACK$32),"") -> 46206 | G18: =IFERROR(E18-H18,"") -> 0.062200546 | H18: =IFERROR(LOOKUP(2,1/(指数走势!$F$32:$ACK$32<F18)/(指数走势!$F$33:$ACK$33<>""),指数走势!$F$33:$ACK$33),"") -> 16.878799 | I18: =IFERROR(LOOKUP(2,1/(指数走势!$F$32:$ACK$32<F18)/(指数走势!$F$33:$ACK$33<>""),指数走势!$F$32:$ACK$32),"") -> 46205
A19: 深证成指PE(TTM) | B19: 日度 | C19: 399001.SZ | D19: 倍 | E19: =IFERROR(LOOKUP(2,1/(指数走势!$F$32:$ACK$32<=$F$3)/(指数走势!$F$34:$ACK$34<>""),指数走势!$F$34:$ACK$34),"") -> 37.180401 | F19: =IFERROR(LOOKUP(2,1/(指数走势!$F$32:$ACK$32<=$F$3)/(指数走势!$F$34:$ACK$34<>""),指数走势!$F$32:$ACK$32),"") -> 46206 | G19: =IFERROR(E19-H19,"") -> 0.31999969 | H19: =IFERROR(LOOKUP(2,1/(指数走势!$F$32:$ACK$32<F19)/(指数走势!$F$34:$ACK$34<>""),指数走势!$F$34:$ACK$34),"") -> 36.860401 | I19: =IFERROR(LOOKUP(2,1/(指数走势!$F$32:$ACK$32<F19)/(指数走势!$F$34:$ACK$34<>""),指数走势!$F$32:$ACK$32),"") -> 46205
A20: 沪深300PE(TTM) | B20: 日度 | C20: 000300.SH | D20: 倍 | E20: =IFERROR(LOOKUP(2,1/(指数走势!$F$32:$ACK$32<=$F$4)/(指数走势!$F$35:$ACK$35<>""),指数走势!$F$35:$ACK$35),"") -> 14.3228 | F20: =IFERROR(LOOKUP(2,1/(指数走势!$F$32:$ACK$32<=$F$4)/(指数走势!$F$35:$ACK$35<>""),指数走势!$F$32:$ACK$32),"") -> 46206 | G20: =IFERROR(E20-H20,"") -> 0.085499763 | H20: =IFERROR(LOOKUP(2,1/(指数走势!$F$32:$ACK$32<F20)/(指数走势!$F$35:$ACK$35<>""),指数走势!$F$35:$ACK$35),"") -> 14.2373 | I20: =IFERROR(LOOKUP(2,1/(指数走势!$F$32:$ACK$32<F20)/(指数走势!$F$35:$ACK$35<>""),指数走势!$F$32:$ACK$32),"") -> 46205
A21: 创业板指PE(TTM) | B21: 日度 | C21: 399006.SZ | D21: 倍 | E21: =IFERROR(LOOKUP(2,1/(指数走势!$F$32:$ACK$32<=$F$5)/(指数走势!$F$36:$ACK$36<>""),指数走势!$F$36:$ACK$36),"") -> 51.1866 | F21: =IFERROR(LOOKUP(2,1/(指数走势!$F$32:$ACK$32<=$F$5)/(指数走势!$F$36:$ACK$36<>""),指数走势!$F$32:$ACK$32),"") -> 46206 | G21: =IFERROR(E21-H21,"") -> 0.11370087 | H21: =IFERROR(LOOKUP(2,1/(指数走势!$F$32:$ACK$32<F21)/(指数走势!$F$36:$ACK$36<>""),指数走势!$F$36:$ACK$36),"") -> 51.072899 | I21: =IFERROR(LOOKUP(2,1/(指数走势!$F$32:$ACK$32<F21)/(指数走势!$F$36:$ACK$36<>""),指数走势!$F$32:$ACK$32),"") -> 46205
A22: 恒生指数PE(TTM) | B22: 日度 | C22: HSI.HI | D22: 倍 | E22: =IFERROR(LOOKUP(2,1/(指数走势!$F$32:$ACK$32<=$F$10)/(指数走势!$F$37:$ACK$37<>""),指数走势!$F$37:$ACK$37),"") -> 11.2894 | F22: =IFERROR(LOOKUP(2,1/(指数走势!$F$32:$ACK$32<=$F$10)/(指数走势!$F$37:$ACK$37<>""),指数走势!$F$32:$ACK$32),"") -> 46206 | G22: =IFERROR(E22-H22,"") -> 0.12720013 | H22: =IFERROR(LOOKUP(2,1/(指数走势!$F$32:$ACK$32<F22)/(指数走势!$F$37:$ACK$37<>""),指数走势!$F$37:$ACK$37),"") -> 11.1622 | I22: =IFERROR(LOOKUP(2,1/(指数走势!$F$32:$ACK$32<F22)/(指数走势!$F$37:$ACK$37<>""),指数走势!$F$32:$ACK$32),"") -> 46205
A23: 恒生科技PE(TTM) | B23: 日度 | C23: HSTECH.HI | D23: 倍 | E23: =IFERROR(LOOKUP(2,1/(指数走势!$F$32:$ACK$32<=$F$11)/(指数走势!$F$38:$ACK$38<>""),指数走势!$F$38:$ACK$38),"") -> 21.8529 | F23: =IFERROR(LOOKUP(2,1/(指数走势!$F$32:$ACK$32<=$F$11)/(指数走势!$F$38:$ACK$38<>""),指数走势!$F$32:$ACK$32),"") -> 46206 | G23: =IFERROR(E23-H23,"") -> 0.17479897 | H23: =IFERROR(LOOKUP(2,1/(指数走势!$F$32:$ACK$32<F23)/(指数走势!$F$38:$ACK$38<>""),指数走势!$F$38:$ACK$38),"") -> 21.678101 | I23: =IFERROR(LOOKUP(2,1/(指数走势!$F$32:$ACK$32<F23)/(指数走势!$F$38:$ACK$38<>""),指数走势!$F$32:$ACK$32),"") -> 46205

Sheet 中债
B1: 频率 | C1: 代码 | D1: 单位 | E1: 当前数据 | F1: 数据日期 | G1: 变化 | H1: 上期数据 | I1: 上期日期 | J1: 趋势图
A2: 1年国债收益率 | B2: 日度 | C2: M0325686 | D2: % | E2: =IFERROR(LOOKUP(9.99E+307,宏观数据!$F$43:$UN$43),"") -> 1.1365 | F2: =IFERROR(LOOKUP(2,1/(宏观数据!$F$43:$UN$43<>""),宏观数据!$F$1:$UN$1),"") -> 46206 | G2: =IFERROR(E2-H2,"") -> 0.0029 | H2: =IFERROR(LOOKUP(9.99E+307,OFFSET(宏观数据!$F$43,0,0,1,LOOKUP(2,1/(宏观数据!$F$43:$UN$43<>""),COLUMN(宏观数据!$F$43:$UN$43))-COLUMN(宏观数据!$F$43))),"") -> 1.1336 | I2: =IFERROR(LOOKUP(2,1/(宏观数据!$F$43:$UN$43<>"")/(宏观数据!$F$1:$UN$1<F2),宏观数据!$F$1:$UN$1),"") -> 46205
A3: 10年国债收益率 | B3: 日度 | C3: S0059749 | D3: % | E3: =IFERROR(LOOKUP(9.99E+307,宏观数据!$F$52:$UN$52),"") -> 1.7463 | F3: =IFERROR(LOOKUP(2,1/(宏观数据!$F$52:$UN$52<>""),宏观数据!$F$1:$UN$1),"") -> 46206 | G3: =IFERROR(E3-H3,"") -> 0.0053 | H3: =IFERROR(LOOKUP(9.99E+307,OFFSET(宏观数据!$F$52,0,0,1,LOOKUP(2,1/(宏观数据!$F$52:$UN$52<>""),COLUMN(宏观数据!$F$52:$UN$52))-COLUMN(宏观数据!$F$52))),"") -> 1.741 | I3: =IFERROR(LOOKUP(2,1/(宏观数据!$F$52:$UN$52<>"")/(宏观数据!$F$1:$UN$1<F3),宏观数据!$F$1:$UN$1),"") -> 46205
A4: 期限利差：（国债）10Y-1Y | B4: 日度 | D4: BP | E4: =IFERROR((E3-E2)*100,"") -> 60.98 | F4: =F2 -> 46206 | G4: =IFERROR(E4-H4,"") -> 0.24 | H4: =IFERROR((H3-H2)*100,"") -> 60.74 | I4: =I2 -> 46205
A5: 信用利差：10Y（企业债-国开债） | B5: 日度 | D5: BP | E5: =IFERROR((LOOKUP(9.99E+307,宏观数据!$F$55:$UN$55)-LOOKUP(9.99E+307,宏观数据!$F$54:$UN$54))*100,"") -> 30.06 | F5: =IFERROR(LOOKUP(2,1/(宏观数据!$F$55:$UN$55<>""),宏观数据!$F$1:$UN$1),"") -> 46206 | G5: =IFERROR(E5-H5,"") -> -0.42 | H5: =IFERROR((LOOKUP(9.99E+307,OFFSET(宏观数据!$F$55,0,0,1,LOOKUP(2,1/(宏观数据!$F$55:$UN$55<>""),COLUMN(宏观数据!$F$55:$UN$55))-COLUMN(宏观数据!$F$55)))-LOOKUP(9.99E+307,OFFSET(宏观数据!$F$54,0,0,1,LOOKUP(2,1/(宏观数据!$F$54:$UN$54<>""),COLUMN(宏观数据!$F$54:$UN$54))-COLUMN(宏观数据!$F$54))))*100,"") -> 30.48 | I5: =I3 -> 46205
A6: 中国:社会融资规模存量:企业债券:同比 | B6: 月度 | C6: M5525769 | D6: % | E6: =IFERROR(LOOKUP(9.99E+307,宏观数据!$F$37:$UN$37),"") -> 8.4 | F6: =IFERROR(LOOKUP(2,1/(宏观数据!$F$37:$UN$37<>""),宏观数据!$F$1:$UN$1),"") -> 46173 | G6: =IFERROR(E6-H6,"") -> 0.1 | H6: =IFERROR(LOOKUP(9.99E+307,OFFSET(宏观数据!$F$37,0,0,1,LOOKUP(2,1/(宏观数据!$F$37:$UN$37<>""),COLUMN(宏观数据!$F$37:$UN$37))-COLUMN(宏观数据!$F$37))),"") -> 8.3 | I6: =IFERROR(LOOKUP(2,1/(宏观数据!$F$37:$UN$37<>"")/(宏观数据!$F$1:$UN$1<F6),宏观数据!$F$1:$UN$1),"") -> 46142
A7: 中债国债到期收益率:2年 | B7: 日度 | C7: S0059745 | D7: % | E7: =IFERROR(LOOKUP(9.99E+307,宏观数据!$F$44:$UN$44),"") -> 1.2473 | F7: =IFERROR(LOOKUP(2,1/(宏观数据!$F$44:$UN$44<>""),宏观数据!$F$1:$UN$1),"") -> 46206 | G7: =IFERROR(E7-H7,"") -> 0.0002 | H7: =IFERROR(LOOKUP(9.99E+307,OFFSET(宏观数据!$F$44,0,0,1,LOOKUP(2,1/(宏观数据!$F$44:$UN$44<>""),COLUMN(宏观数据!$F$44:$UN$44))-COLUMN(宏观数据!$F$44))),"") -> 1.2471 | I7: =IFERROR(LOOKUP(2,1/(宏观数据!$F$44:$UN$44<>"")/(宏观数据!$F$1:$UN$1<F7),宏观数据!$F$1:$UN$1),"") -> 46205
A8: 中债国债到期收益率:3年 | B8: 日度 | C8: S0059746 | D8: % | E8: =IFERROR(LOOKUP(9.99E+307,宏观数据!$F$45:$UN$45),"") -> 1.2901 | F8: =IFERROR(LOOKUP(2,1/(宏观数据!$F$45:$UN$45<>""),宏观数据!$F$1:$UN$1),"") -> 46206 | G8: =IFERROR(E8-H8,"") -> -0.0026 | H8: =IFERROR(LOOKUP(9.99E+307,OFFSET(宏观数据!$F$45,0,0,1,LOOKUP(2,1/(宏观数据!$F$45:$UN$45<>""),COLUMN(宏观数据!$F$45:$UN$45))-COLUMN(宏观数据!$F$45))),"") -> 1.2927 | I8: =IFERROR(LOOKUP(2,1/(宏观数据!$F$45:$UN$45<>"")/(宏观数据!$F$1:$UN$1<F8),宏观数据!$F$1:$UN$1),"") -> 46205
A9: 中债国开债到期收益率:3年 | B9: 日度 | C9: M1004265 | D9: % | E9: =IFERROR(LOOKUP(9.99E+307,宏观数据!$F$46:$UN$46),"") -> 1.4701 | F9: =IFERROR(LOOKUP(2,1/(宏观数据!$F$46:$UN$46<>""),宏观数据!$F$1:$UN$1),"") -> 46206 | G9: =IFERROR(E9-H9,"") -> -0.003 | H9: =IFERROR(LOOKUP(9.99E+307,OFFSET(宏观数据!$F$46,0,0,1,LOOKUP(2,1/(宏观数据!$F$46:$UN$46<>""),COLUMN(宏观数据!$F$46:$UN$46))-COLUMN(宏观数据!$F$46))),"") -> 1.4731 | I9: =IFERROR(LOOKUP(2,1/(宏观数据!$F$46:$UN$46<>"")/(宏观数据!$F$1:$UN$1<F9),宏观数据!$F$1:$UN$1),"") -> 46205
A10: 中债国开债到期收益率:1年 | B10: 日度 | C10: M1004263 | D10: % | E10: =IFERROR(LOOKUP(9.99E+307,宏观数据!$F$47:$UN$47),"") -> 1.3566 | F10: =IFERROR(LOOKUP(2,1/(宏观数据!$F$47:$UN$47<>""),宏观数据!$F$1:$UN$1),"") -> 46206 | G10: =IFERROR(E10-H10,"") -> -0.005 | H10: =IFERROR(LOOKUP(9.99E+307,OFFSET(宏观数据!$F$47,0,0,1,LOOKUP(2,1/(宏观数据!$F$47:$UN$47<>""),COLUMN(宏观数据!$F$47:$UN$47))-COLUMN(宏观数据!$F$47))),"") -> 1.3616 | I10: =IFERROR(LOOKUP(2,1/(宏观数据!$F$47:$UN$47<>"")/(宏观数据!$F$1:$UN$1<F10),宏观数据!$F$1:$UN$1),"") -> 46205
A11: 中债企业债到期收益率(AAA):1年 | B11: 日度 | C11: S0059771 | D11: % | E11: =IFERROR(LOOKUP(9.99E+307,宏观数据!$F$48:$UN$48),"") -> 1.505 | F11: =IFERROR(LOOKUP(2,1/(宏观数据!$F$48:$UN$48<>""),宏观数据!$F$1:$UN$1),"") -> 46206 | G11: =IFERROR(E11-H11,"") -> 0 | H11: =IFERROR(LOOKUP(9.99E+307,OFFSET(宏观数据!$F$48,0,0,1,LOOKUP(2,1/(宏观数据!$F$48:$UN$48<>""),COLUMN(宏观数据!$F$48:$UN$48))-COLUMN(宏观数据!$F$48))),"") -> 1.505 | I11: =IFERROR(LOOKUP(2,1/(宏观数据!$F$48:$UN$48<>"")/(宏观数据!$F$1:$UN$1<F11),宏观数据!$F$1:$UN$1),"") -> 46205
A12: 中债城投债到期收益率(AAA):1年 | B12: 日度 | C12: M0048432 | D12: % | E12: =IFERROR(LOOKUP(9.99E+307,宏观数据!$F$49:$UN$49),"") -> 1.5297 | F12: =IFERROR(LOOKUP(2,1/(宏观数据!$F$49:$UN$49<>""),宏观数据!$F$1:$UN$1),"") -> 46206 | G12: =IFERROR(E12-H12,"") -> -0.0019 | H12: =IFERROR(LOOKUP(9.99E+307,OFFSET(宏观数据!$F$49,0,0,1,LOOKUP(2,1/(宏观数据!$F$49:$UN$49<>""),COLUMN(宏观数据!$F$49:$UN$49))-COLUMN(宏观数据!$F$49))),"") -> 1.5316 | I12: =IFERROR(LOOKUP(2,1/(宏观数据!$F$49:$UN$49<>"")/(宏观数据!$F$1:$UN$1<F12),宏观数据!$F$1:$UN$1),"") -> 46205
A13: 中债城投债到期收益率(AAA):3年 | B13: 日度 | C13: M0048434 | D13: % | E13: =IFERROR(LOOKUP(9.99E+307,宏观数据!$F$50:$UN$50),"") -> 1.6675 | F13: =IFERROR(LOOKUP(2,1/(宏观数据!$F$50:$UN$50<>""),宏观数据!$F$1:$UN$1),"") -> 46206 | G13: =IFERROR(E13-H13,"") -> 0.0043 | H13: =IFERROR(LOOKUP(9.99E+307,OFFSET(宏观数据!$F$50,0,0,1,LOOKUP(2,1/(宏观数据!$F$50:$UN$50<>""),COLUMN(宏观数据!$F$50:$UN$50))-COLUMN(宏观数据!$F$50))),"") -> 1.6632 | I13: =IFERROR(LOOKUP(2,1/(宏观数据!$F$50:$UN$50<>"")/(宏观数据!$F$1:$UN$1<F13),宏观数据!$F$1:$UN$1),"") -> 46205
A14: 中债企业债到期收益率(AAA):3年 | B14: 日度 | C14: S0059773 | D14: % | E14: =IFERROR(LOOKUP(9.99E+307,宏观数据!$F$51:$UN$51),"") -> 1.643 | F14: =IFERROR(LOOKUP(2,1/(宏观数据!$F$51:$UN$51<>""),宏观数据!$F$1:$UN$1),"") -> 46206 | G14: =IFERROR(E14-H14,"") -> 0 | H14: =IFERROR(LOOKUP(9.99E+307,OFFSET(宏观数据!$F$51,0,0,1,LOOKUP(2,1/(宏观数据!$F$51:$UN$51<>""),COLUMN(宏观数据!$F$51:$UN$51))-COLUMN(宏观数据!$F$51))),"") -> 1.643 | I14: =IFERROR(LOOKUP(2,1/(宏观数据!$F$51:$UN$51<>"")/(宏观数据!$F$1:$UN$1<F14),宏观数据!$F$1:$UN$1),"") -> 46205
A15: 中债国债到期收益率:30年 | B15: 日度 | C15: S0059752 | D15: % | E15: =IFERROR(LOOKUP(9.99E+307,宏观数据!$F$53:$UN$53),"") -> 2.2685 | F15: =IFERROR(LOOKUP(2,1/(宏观数据!$F$53:$UN$53<>""),宏观数据!$F$1:$UN$1),"") -> 46206 | G15: =IFERROR(E15-H15,"") -> 0.0105 | H15: =IFERROR(LOOKUP(9.99E+307,OFFSET(宏观数据!$F$53,0,0,1,LOOKUP(2,1/(宏观数据!$F$53:$UN$53<>""),COLUMN(宏观数据!$F$53:$UN$53))-COLUMN(宏观数据!$F$53))),"") -> 2.258 | I15: =IFERROR(LOOKUP(2,1/(宏观数据!$F$53:$UN$53<>"")/(宏观数据!$F$1:$UN$1<F15),宏观数据!$F$1:$UN$1),"") -> 46205
A16: 中债国开债到期收益率:10年 | B16: 日度 | C16: M1004271 | D16: % | E16: =IFERROR(LOOKUP(9.99E+307,宏观数据!$F$54:$UN$54),"") -> 1.797 | F16: =IFERROR(LOOKUP(2,1/(宏观数据!$F$54:$UN$54<>""),宏观数据!$F$1:$UN$1),"") -> 46206 | G16: =IFERROR(E16-H16,"") -> 0.004 | H16: =IFERROR(LOOKUP(9.99E+307,OFFSET(宏观数据!$F$54,0,0,1,LOOKUP(2,1/(宏观数据!$F$54:$UN$54<>""),COLUMN(宏观数据!$F$54:$UN$54))-COLUMN(宏观数据!$F$54))),"") -> 1.793 | I16: =IFERROR(LOOKUP(2,1/(宏观数据!$F$54:$UN$54<>"")/(宏观数据!$F$1:$UN$1<F16),宏观数据!$F$1:$UN$1),"") -> 46205
A17: 中债企业债到期收益率(AAA):10年 | B17: 日度 | C17: S0059776 | D17: % | E17: =IFERROR(LOOKUP(9.99E+307,宏观数据!$F$55:$UN$55),"") -> 2.0976 | F17: =IFERROR(LOOKUP(2,1/(宏观数据!$F$55:$UN$55<>""),宏观数据!$F$1:$UN$1),"") -> 46206 | G17: =IFERROR(E17-H17,"") -> -0.0002 | H17: =IFERROR(LOOKUP(9.99E+307,OFFSET(宏观数据!$F$55,0,0,1,LOOKUP(2,1/(宏观数据!$F$55:$UN$55<>""),COLUMN(宏观数据!$F$55:$UN$55))-COLUMN(宏观数据!$F$55))),"") -> 2.0978 | I17: =IFERROR(LOOKUP(2,1/(宏观数据!$F$55:$UN$55<>"")/(宏观数据!$F$1:$UN$1<F17),宏观数据!$F$1:$UN$1),"") -> 46205
A18: 中债城投债到期收益率(AAA):10年 | B18: 日度 | C18: M0048437 | D18: % | E18: =IFERROR(LOOKUP(9.99E+307,宏观数据!$F$56:$UN$56),"") -> 2.1476 | F18: =IFERROR(LOOKUP(2,1/(宏观数据!$F$56:$UN$56<>""),宏观数据!$F$1:$UN$1),"") -> 46206 | G18: =IFERROR(E18-H18,"") -> 0.0018 | H18: =IFERROR(LOOKUP(9.99E+307,OFFSET(宏观数据!$F$56,0,0,1,LOOKUP(2,1/(宏观数据!$F$56:$UN$56<>""),COLUMN(宏观数据!$F$56:$UN$56))-COLUMN(宏观数据!$F$56))),"") -> 2.1458 | I18: =IFERROR(LOOKUP(2,1/(宏观数据!$F$56:$UN$56<>"")/(宏观数据!$F$1:$UN$1<F18),宏观数据!$F$1:$UN$1),"") -> 46205
A19: DR001 | B19: 日度 | C19: M1006336 | E19: =IFERROR(LOOKUP(9.99E+307,宏观数据!$F$81:$UN$81),"") -> 1.3608 | F19: =IFERROR(LOOKUP(2,1/(宏观数据!$F$81:$UN$81<>""),宏观数据!$F$1:$UN$1),"") -> 46206 | G19: =IFERROR(E19-H19,"") -> -0.044 | H19: =IFERROR(LOOKUP(9.99E+307,OFFSET(宏观数据!$F$81,0,0,1,LOOKUP(2,1/(宏观数据!$F$81:$UN$81<>""),COLUMN(宏观数据!$F$81:$UN$81))-COLUMN(宏观数据!$F$81))),"") -> 1.4048 | I19: =IFERROR(LOOKUP(2,1/(宏观数据!$F$81:$UN$81<>"")/(宏观数据!$F$1:$UN$1<F19),宏观数据!$F$1:$UN$1),"") -> 46205
A20: DR007 | B20: 日度 | C20: M1006337 | E20: =IFERROR(LOOKUP(9.99E+307,宏观数据!$F$82:$UN$82),"") -> 1.3924 | F20: =IFERROR(LOOKUP(2,1/(宏观数据!$F$82:$UN$82<>""),宏观数据!$F$1:$UN$1),"") -> 46206 | G20: =IFERROR(E20-H20,"") -> -0.0354 | H20: =IFERROR(LOOKUP(9.99E+307,OFFSET(宏观数据!$F$82,0,0,1,LOOKUP(2,1/(宏观数据!$F$82:$UN$82<>""),COLUMN(宏观数据!$F$82:$UN$82))-COLUMN(宏观数据!$F$82))),"") -> 1.4278 | I20: =IFERROR(LOOKUP(2,1/(宏观数据!$F$82:$UN$82<>"")/(宏观数据!$F$1:$UN$1<F20),宏观数据!$F$1:$UN$1),"") -> 46205
A21: R001 | B21: 日度 | C21: M1001794 | E21: =IFERROR(LOOKUP(9.99E+307,宏观数据!$F$83:$UN$83),"") -> 1.3861 | F21: =IFERROR(LOOKUP(2,1/(宏观数据!$F$83:$UN$83<>""),宏观数据!$F$1:$UN$1),"") -> 46206 | G21: =IFERROR(E21-H21,"") -> -0.0503 | H21: =IFERROR(LOOKUP(9.99E+307,OFFSET(宏观数据!$F$83,0,0,1,LOOKUP(2,1/(宏观数据!$F$83:$UN$83<>""),COLUMN(宏观数据!$F$83:$UN$83))-COLUMN(宏观数据!$F$83))),"") -> 1.4364 | I21: =IFERROR(LOOKUP(2,1/(宏观数据!$F$83:$UN$83<>"")/(宏观数据!$F$1:$UN$1<F21),宏观数据!$F$1:$UN$1),"") -> 46205
A22: R007 | B22: 日度 | C22: M1001795 | E22: =IFERROR(LOOKUP(9.99E+307,宏观数据!$F$84:$UN$84),"") -> 1.4225 | F22: =IFERROR(LOOKUP(2,1/(宏观数据!$F$84:$UN$84<>""),宏观数据!$F$1:$UN$1),"") -> 46206 | G22: =IFERROR(E22-H22,"") -> -0.0612 | H22: =IFERROR(LOOKUP(9.99E+307,OFFSET(宏观数据!$F$84,0,0,1,LOOKUP(2,1/(宏观数据!$F$84:$UN$84<>""),COLUMN(宏观数据!$F$84:$UN$84))-COLUMN(宏观数据!$F$84))),"") -> 1.4837 | I22: =IFERROR(LOOKUP(2,1/(宏观数据!$F$84:$UN$84<>"")/(宏观数据!$F$1:$UN$1<F22),宏观数据!$F$1:$UN$1),"") -> 46205
A23: 中国:同业存单到期收益率(AAA):1年 | B23: 日度 | C23: M1004902 | D23: % | E23: =IFERROR(LOOKUP(9.99E+307,宏观数据!$F$106:$UN$106),"") -> 1.465 | F23: =IFERROR(LOOKUP(2,1/(宏观数据!$F$106:$UN$106<>""),宏观数据!$F$1:$UN$1),"") -> 46206 | G23: =IFERROR(E23-H23,"") -> -0.005 | H23: =IFERROR(LOOKUP(9.99E+307,OFFSET(宏观数据!$F$106,0,0,1,LOOKUP(2,1/(宏观数据!$F$106:$UN$106<>""),COLUMN(宏观数据!$F$106:$UN$106))-COLUMN(宏观数据!$F$106))),"") -> 1.47 | I23: =IFERROR(LOOKUP(2,1/(宏观数据!$F$106:$UN$106<>"")/(宏观数据!$F$1:$UN$1<F23),宏观数据!$F$1:$UN$1),"") -> 46205
A24: 中国:社会融资规模:企业债券融资:当月值 | B24: 月度 | C24: M5206736 | D24: 亿元 | E24: =IFERROR(LOOKUP(9.99E+307,宏观数据!$F$117:$UN$117),"") -> 1680 | F24: =IFERROR(LOOKUP(2,1/(宏观数据!$F$117:$UN$117<>""),宏观数据!$F$1:$UN$1),"") -> 46173 | G24: =IFERROR(E24-H24,"") -> -2840 | H24: =IFERROR(LOOKUP(9.99E+307,OFFSET(宏观数据!$F$117,0,0,1,LOOKUP(2,1/(宏观数据!$F$117:$UN$117<>""),COLUMN(宏观数据!$F$117:$UN$117))-COLUMN(宏观数据!$F$117))),"") -> 4520 | I24: =IFERROR(LOOKUP(2,1/(宏观数据!$F$117:$UN$117<>"")/(宏观数据!$F$1:$UN$1<F24),宏观数据!$F$1:$UN$1),"") -> 46142
A25: SHIBOR:3个月 | B25: 日度 | C25: M0017142 | D25: % | E25: =IFERROR(LOOKUP(9.99E+307,宏观数据!$F$151:$UN$151),"") -> 1.435 | F25: =IFERROR(LOOKUP(2,1/(宏观数据!$F$151:$UN$151<>""),宏观数据!$F$1:$UN$1),"") -> 46206 | G25: =IFERROR(E25-H25,"") -> -0.002 | H25: =IFERROR(LOOKUP(9.99E+307,OFFSET(宏观数据!$F$151,0,0,1,LOOKUP(2,1/(宏观数据!$F$151:$UN$151<>""),COLUMN(宏观数据!$F$151:$UN$151))-COLUMN(宏观数据!$F$151))),"") -> 1.437 | I25: =IFERROR(LOOKUP(2,1/(宏观数据!$F$151:$UN$151<>"")/(宏观数据!$F$1:$UN$1<F25),宏观数据!$F$1:$UN$1),"") -> 46205
A26: 中国:贷款市场报价利率(LPR):1年 | B26: 月度 | C26: M0096870 | D26: % | E26: =IFERROR(LOOKUP(9.99E+307,宏观数据!$F$155:$UN$155),"") -> 3 | F26: =IFERROR(LOOKUP(2,1/(宏观数据!$F$155:$UN$155<>""),宏观数据!$F$1:$UN$1),"") -> 46195 | G26: =IFERROR(E26-H26,"") -> 0 | H26: =IFERROR(LOOKUP(9.99E+307,OFFSET(宏观数据!$F$155,0,0,1,LOOKUP(2,1/(宏观数据!$F$155:$UN$155<>""),COLUMN(宏观数据!$F$155:$UN$155))-COLUMN(宏观数据!$F$155))),"") -> 3 | I26: =IFERROR(LOOKUP(2,1/(宏观数据!$F$155:$UN$155<>"")/(宏观数据!$F$1:$UN$1<F26),宏观数据!$F$1:$UN$1),"") -> 46162
A27: 中国:国债收益率:10年 | B27: 日度 | C27: M0325687 | D27: % | E27: =IFERROR(LOOKUP(9.99E+307,宏观数据!$F$156:$UN$156),"") -> 1.7423 | F27: =IFERROR(LOOKUP(2,1/(宏观数据!$F$156:$UN$156<>""),宏观数据!$F$1:$UN$1),"") -> 46206 | G27: =IFERROR(E27-H27,"") -> 0.0054 | H27: =IFERROR(LOOKUP(9.99E+307,OFFSET(宏观数据!$F$156,0,0,1,LOOKUP(2,1/(宏观数据!$F$156:$UN$156<>""),COLUMN(宏观数据!$F$156:$UN$156))-COLUMN(宏观数据!$F$156))),"") -> 1.7369 | I27: =IFERROR(LOOKUP(2,1/(宏观数据!$F$156:$UN$156<>"")/(宏观数据!$F$1:$UN$1<F27),宏观数据!$F$1:$UN$1),"") -> 46205
A28: 中美10年期国债利差 (中-美) | B28: 日度 | C28: M0325687-G0000891 | D28: % | E28: =IFERROR(LOOKUP(9.99E+307,宏观数据!$F$176:$UN$176),"") -> -2.7069 | F28: =IFERROR(LOOKUP(2,1/(宏观数据!$F$176:$UN$176<>""),宏观数据!$F$1:$UN$1),"") -> 46185 | G28: =IFERROR(E28-H28,"") -> -0.0312 | H28: =IFERROR(LOOKUP(9.99E+307,OFFSET(宏观数据!$F$176,0,0,1,LOOKUP(2,1/(宏观数据!$F$176:$UN$176<>""),COLUMN(宏观数据!$F$176:$UN$176))-COLUMN(宏观数据!$F$176))),"") -> -2.6757 | I28: =IFERROR(LOOKUP(2,1/(宏观数据!$F$176:$UN$176<>"")/(宏观数据!$F$1:$UN$1<F28),宏观数据!$F$1:$UN$1),"") -> 46184

Sheet 中国宏观
B1: 频率 | C1: 代码 | D1: 单位 | E1: 当前数据 | F1: 数据日期 | G1: 变化 | H1: 上期数据 | I1: 上期日期 | J1: 趋势图
A2: 7天逆回购 | B2: 日度 | C2: M0041371 | D2: % | E2: =IFERROR(LOOKUP(9.99E+307,宏观数据!$F$85:$UN$85),"") -> 1.4 | F2: =IFERROR(LOOKUP(2,1/(宏观数据!$F$85:$UN$85<>""),宏观数据!$F$1:$UN$1),"") -> 46209 | G2: =IFERROR(E2-H2,"") -> 0 | H2: =IFERROR(LOOKUP(9.99E+307,OFFSET(宏观数据!$F$85,0,0,1,LOOKUP(2,1/(宏观数据!$F$85:$UN$85<>""),COLUMN(宏观数据!$F$85:$UN$85))-COLUMN(宏观数据!$F$85))),"") -> 1.4 | I2: =IFERROR(LOOKUP(2,1/(宏观数据!$F$85:$UN$85<>"")/(宏观数据!$F$1:$UN$1<F2),宏观数据!$F$1:$UN$1),"") -> 46206
A3: 法定存准率 | B3: 月度 | C3: M0061518 | D3: % | E3: =IFERROR(LOOKUP(9.99E+307,宏观数据!$F$27:$UN$27),"") -> 9 | F3: =IFERROR(LOOKUP(2,1/(宏观数据!$F$27:$UN$27<>""),宏观数据!$F$1:$UN$1),"") -> 46203 | G3: =IFERROR(E3-H3,"") -> 0 | H3: =IFERROR(LOOKUP(9.99E+307,OFFSET(宏观数据!$F$27,0,0,1,LOOKUP(2,1/(宏观数据!$F$27:$UN$27<>""),COLUMN(宏观数据!$F$27:$UN$27))-COLUMN(宏观数据!$F$27))),"") -> 9 | I3: =IFERROR(LOOKUP(2,1/(宏观数据!$F$27:$UN$27<>"")/(宏观数据!$F$1:$UN$1<F3),宏观数据!$F$1:$UN$1),"") -> 46173
A4: 公开市场操作净投放 | B4: 日度 | C4: A4087688 | D4: 亿元 | E4: =IFERROR(LOOKUP(9.99E+307,宏观数据!$F$79:$UN$79),"") -> 495 | F4: =IFERROR(LOOKUP(2,1/(宏观数据!$F$79:$UN$79<>""),宏观数据!$F$1:$UN$1),"") -> 46209 | G4: =IFERROR(E4-H4,"") -> 2180 | H4: =IFERROR(LOOKUP(9.99E+307,OFFSET(宏观数据!$F$79,0,0,1,LOOKUP(2,1/(宏观数据!$F$79:$UN$79<>""),COLUMN(宏观数据!$F$79:$UN$79))-COLUMN(宏观数据!$F$79))),"") -> -1685 | I4: =IFERROR(LOOKUP(2,1/(宏观数据!$F$79:$UN$79<>"")/(宏观数据!$F$1:$UN$1<F4),宏观数据!$F$1:$UN$1),"") -> 46206
A5: 中央银行贷款-总投放 | B5: 月度 | C5: N7822723+Z0569230+Z7194825+P5747228+C8808133 | E5: =IFERROR(IFERROR(LOOKUP(9.99E+307,宏观数据!$F$28:$UN$28),0)+IFERROR(LOOKUP(9.99E+307,宏观数据!$F$29:$UN$29),0)+IFERROR(LOOKUP(9.99E+307,宏观数据!$F$30:$UN$30),0)+IFERROR(LOOKUP(9.99E+307,宏观数据!$F$31:$UN$31),0)+IFERROR(LOOKUP(9.99E+307,宏观数据!$F$32:$UN$32),0),"") -> 10128 | F5: =IFERROR(LOOKUP(2,1/(宏观数据!$F$29:$UN$29<>""),宏观数据!$F$1:$UN$1),"") -> 46203 | G5: =IFERROR(E5-H5,"") -> 9535 | H5: =IFERROR(IFERROR(LOOKUP(9.99E+307,OFFSET(宏观数据!$F$28,0,0,1,LOOKUP(2,1/(宏观数据!$F$28:$UN$28<>""),COLUMN(宏观数据!$F$28:$UN$28))-COLUMN(宏观数据!$F$28))),0)+IFERROR(LOOKUP(9.99E+307,OFFSET(宏观数据!$F$29,0,0,1,LOOKUP(2,1/(宏观数据!$F$29:$UN$29<>""),COLUMN(宏观数据!$F$29:$UN$29))-COLUMN(宏观数据!$F$29))),0)+IFERROR(LOOKUP(9.99E+307,OFFSET(宏观数据!$F$30,0,0,1,LOOKUP(2,1/(宏观数据!$F$30:$UN$30<>""),COLUMN(宏观数据!$F$30:$UN$30))-COLUMN(宏观数据!$F$30))),0)+IFERROR(LOOKUP(9.99E+307,OFFSET(宏观数据!$F$31,0,0,1,LOOKUP(2,1/(宏观数据!$F$31:$UN$31<>""),COLUMN(宏观数据!$F$31:$UN$31))-COLUMN(宏观数据!$F$31))),0)+IFERROR(LOOKUP(9.99E+307,OFFSET(宏观数据!$F$32,0,0,1,LOOKUP(2,1/(宏观数据!$F$32:$UN$32<>""),COLUMN(宏观数据!$F$32:$UN$32))-COLUMN(宏观数据!$F$32))),0),"") -> 593 | I5: =IFERROR(LOOKUP(2,1/(宏观数据!$F$29:$UN$29<>"")/(宏观数据!$F$1:$UN$1<F5),宏观数据!$F$1:$UN$1),"") -> 46173
A6: DR001 | B6: 日度 | C6: M1006336 | D6: % | E6: =IFERROR(LOOKUP(9.99E+307,宏观数据!$F$81:$UN$81),"") -> 1.3608 | F6: =IFERROR(LOOKUP(2,1/(宏观数据!$F$81:$UN$81<>""),宏观数据!$F$1:$UN$1),"") -> 46206 | G6: =IFERROR(E6-H6,"") -> -0.044 | H6: =IFERROR(LOOKUP(9.99E+307,OFFSET(宏观数据!$F$81,0,0,1,LOOKUP(2,1/(宏观数据!$F$81:$UN$81<>""),COLUMN(宏观数据!$F$81:$UN$81))-COLUMN(宏观数据!$F$81))),"") -> 1.4048 | I6: =IFERROR(LOOKUP(2,1/(宏观数据!$F$81:$UN$81<>"")/(宏观数据!$F$1:$UN$1<F6),宏观数据!$F$1:$UN$1),"") -> 46205
A7: DR007 | B7: 日度 | C7: M1006337 | D7: % | E7: =IFERROR(LOOKUP(9.99E+307,宏观数据!$F$82:$UN$82),"") -> 1.3924 | F7: =IFERROR(LOOKUP(2,1/(宏观数据!$F$82:$UN$82<>""),宏观数据!$F$1:$UN$1),"") -> 46206 | G7: =IFERROR(E7-H7,"") -> -0.0354 | H7: =IFERROR(LOOKUP(9.99E+307,OFFSET(宏观数据!$F$82,0,0,1,LOOKUP(2,1/(宏观数据!$F$82:$UN$82<>""),COLUMN(宏观数据!$F$82:$UN$82))-COLUMN(宏观数据!$F$82))),"") -> 1.4278 | I7: =IFERROR(LOOKUP(2,1/(宏观数据!$F$82:$UN$82<>"")/(宏观数据!$F$1:$UN$1<F7),宏观数据!$F$1:$UN$1),"") -> 46205
A8: R001 | B8: 日度 | C8: M1001794 | D8: % | E8: =IFERROR(LOOKUP(9.99E+307,宏观数据!$F$83:$UN$83),"") -> 1.3861 | F8: =IFERROR(LOOKUP(2,1/(宏观数据!$F$83:$UN$83<>""),宏观数据!$F$1:$UN$1),"") -> 46206 | G8: =IFERROR(E8-H8,"") -> -0.0503 | H8: =IFERROR(LOOKUP(9.99E+307,OFFSET(宏观数据!$F$83,0,0,1,LOOKUP(2,1/(宏观数据!$F$83:$UN$83<>""),COLUMN(宏观数据!$F$83:$UN$83))-COLUMN(宏观数据!$F$83))),"") -> 1.4364 | I8: =IFERROR(LOOKUP(2,1/(宏观数据!$F$83:$UN$83<>"")/(宏观数据!$F$1:$UN$1<F8),宏观数据!$F$1:$UN$1),"") -> 46205
A9: R007 | B9: 日度 | C9: M1001795 | D9: % | E9: =IFERROR(LOOKUP(9.99E+307,宏观数据!$F$84:$UN$84),"") -> 1.4225 | F9: =IFERROR(LOOKUP(2,1/(宏观数据!$F$84:$UN$84<>""),宏观数据!$F$1:$UN$1),"") -> 46206 | G9: =IFERROR(E9-H9,"") -> -0.0612 | H9: =IFERROR(LOOKUP(9.99E+307,OFFSET(宏观数据!$F$84,0,0,1,LOOKUP(2,1/(宏观数据!$F$84:$UN$84<>""),COLUMN(宏观数据!$F$84:$UN$84))-COLUMN(宏观数据!$F$84))),"") -> 1.4837 | I9: =IFERROR(LOOKUP(2,1/(宏观数据!$F$84:$UN$84<>"")/(宏观数据!$F$1:$UN$1<F9),宏观数据!$F$1:$UN$1),"") -> 46205
A10: 社融存量 | B10: 月度 | C10: M5525763 | D10: % | E10: =IFERROR(LOOKUP(9.99E+307,宏观数据!$F$33:$UN$33),"") -> 7.7 | F10: =IFERROR(LOOKUP(2,1/(宏观数据!$F$33:$UN$33<>""),宏观数据!$F$1:$UN$1),"") -> 46173 | G10: =IFERROR(E10-H10,"") -> -0.1 | H10: =IFERROR(LOOKUP(9.99E+307,OFFSET(宏观数据!$F$33,0,0,1,LOOKUP(2,1/(宏观数据!$F$33:$UN$33<>""),COLUMN(宏观数据!$F$33:$UN$33))-COLUMN(宏观数据!$F$33))),"") -> 7.8 | I10: =IFERROR(LOOKUP(2,1/(宏观数据!$F$33:$UN$33<>"")/(宏观数据!$F$1:$UN$1<F10),宏观数据!$F$1:$UN$1),"") -> 46142
A11: 新增人民币贷款 | B11: 月度 | C11: M5525764 | D11: % | E11: =IFERROR(LOOKUP(9.99E+307,宏观数据!$F$35:$UN$35),"") -> 5.5 | F11: =IFERROR(LOOKUP(2,1/(宏观数据!$F$35:$UN$35<>""),宏观数据!$F$1:$UN$1),"") -> 46173 | G11: =IFERROR(E11-H11,"") -> -0.1 | H11: =IFERROR(LOOKUP(9.99E+307,OFFSET(宏观数据!$F$35,0,0,1,LOOKUP(2,1/(宏观数据!$F$35:$UN$35<>""),COLUMN(宏观数据!$F$35:$UN$35))-COLUMN(宏观数据!$F$35))),"") -> 5.6 | I11: =IFERROR(LOOKUP(2,1/(宏观数据!$F$35:$UN$35<>"")/(宏观数据!$F$1:$UN$1<F11),宏观数据!$F$1:$UN$1),"") -> 46142
A12: M1 | B12: 月度 | C12: M0001383 | D12: % | E12: =IFERROR(LOOKUP(9.99E+307,宏观数据!$F$39:$UN$39),"") -> 5.5 | F12: =IFERROR(LOOKUP(2,1/(宏观数据!$F$39:$UN$39<>""),宏观数据!$F$1:$UN$1),"") -> 46173 | G12: =IFERROR(E12-H12,"") -> 0.5 | H12: =IFERROR(LOOKUP(9.99E+307,OFFSET(宏观数据!$F$39,0,0,1,LOOKUP(2,1/(宏观数据!$F$39:$UN$39<>""),COLUMN(宏观数据!$F$39:$UN$39))-COLUMN(宏观数据!$F$39))),"") -> 5 | I12: =IFERROR(LOOKUP(2,1/(宏观数据!$F$39:$UN$39<>"")/(宏观数据!$F$1:$UN$1<F12),宏观数据!$F$1:$UN$1),"") -> 46142
A13: M2 | B13: 月度 | C13: M0001385 | D13: % | E13: =IFERROR(LOOKUP(9.99E+307,宏观数据!$F$41:$UN$41),"") -> 8.6 | F13: =IFERROR(LOOKUP(2,1/(宏观数据!$F$41:$UN$41<>""),宏观数据!$F$1:$UN$1),"") -> 46173 | G13: =IFERROR(E13-H13,"") -> 0 | H13: =IFERROR(LOOKUP(9.99E+307,OFFSET(宏观数据!$F$41,0,0,1,LOOKUP(2,1/(宏观数据!$F$41:$UN$41<>""),COLUMN(宏观数据!$F$41:$UN$41))-COLUMN(宏观数据!$F$41))),"") -> 8.6 | I13: =IFERROR(LOOKUP(2,1/(宏观数据!$F$41:$UN$41<>"")/(宏观数据!$F$1:$UN$1<F13),宏观数据!$F$1:$UN$1),"") -> 46142
A14: 社零 | B14: 月度 | C14: M0001428 | D14: % | E14: =IFERROR(LOOKUP(9.99E+307,宏观数据!$F$9:$UN$9),"") -> -0.6 | F14: =IFERROR(LOOKUP(2,1/(宏观数据!$F$9:$UN$9<>""),宏观数据!$F$1:$UN$1),"") -> 46173 | G14: =IFERROR(E14-H14,"") -> -0.8 | H14: =IFERROR(LOOKUP(9.99E+307,OFFSET(宏观数据!$F$9,0,0,1,LOOKUP(2,1/(宏观数据!$F$9:$UN$9<>""),COLUMN(宏观数据!$F$9:$UN$9))-COLUMN(宏观数据!$F$9))),"") -> 0.2 | I14: =IFERROR(LOOKUP(2,1/(宏观数据!$F$9:$UN$9<>"")/(宏观数据!$F$1:$UN$1<F14),宏观数据!$F$1:$UN$1),"") -> 46142
A15: 固定投资 | B15: 月度 | C15: M0000273 | D15: % | E15: =IFERROR(LOOKUP(9.99E+307,宏观数据!$F$15:$UN$15),"") -> -4.1 | F15: =IFERROR(LOOKUP(2,1/(宏观数据!$F$15:$UN$15<>""),宏观数据!$F$1:$UN$1),"") -> 46173 | G15: =IFERROR(E15-H15,"") -> -2.5 | H15: =IFERROR(LOOKUP(9.99E+307,OFFSET(宏观数据!$F$15,0,0,1,LOOKUP(2,1/(宏观数据!$F$15:$UN$15<>""),COLUMN(宏观数据!$F$15:$UN$15))-COLUMN(宏观数据!$F$15))),"") -> -1.6 | I15: =IFERROR(LOOKUP(2,1/(宏观数据!$F$15:$UN$15<>"")/(宏观数据!$F$1:$UN$1<F15),宏观数据!$F$1:$UN$1),"") -> 46142
A16: 房屋销售 | B16: 月度 | C16: S0073300 | D16: % | E16: =IFERROR(LOOKUP(9.99E+307,宏观数据!$F$105:$UN$105),"") -> -10.8 | F16: =IFERROR(LOOKUP(2,1/(宏观数据!$F$105:$UN$105<>""),宏观数据!$F$1:$UN$1),"") -> 46173 | G16: =IFERROR(E16-H16,"") -> -0.6 | H16: =IFERROR(LOOKUP(9.99E+307,OFFSET(宏观数据!$F$105,0,0,1,LOOKUP(2,1/(宏观数据!$F$105:$UN$105<>""),COLUMN(宏观数据!$F$105:$UN$105))-COLUMN(宏观数据!$F$105))),"") -> -10.2 | I16: =IFERROR(LOOKUP(2,1/(宏观数据!$F$105:$UN$105<>"")/(宏观数据!$F$1:$UN$1<F16),宏观数据!$F$1:$UN$1),"") -> 46142
A17: 制造业PMI | B17: 月度 | C17: M0017126 | D17: % | E17: =IFERROR(LOOKUP(9.99E+307,宏观数据!$F$3:$UN$3),"") -> 50.3 | F17: =IFERROR(LOOKUP(2,1/(宏观数据!$F$3:$UN$3<>""),宏观数据!$F$1:$UN$1),"") -> 46203 | G17: =IFERROR(E17-H17,"") -> 0.3 | H17: =IFERROR(LOOKUP(9.99E+307,OFFSET(宏观数据!$F$3,0,0,1,LOOKUP(2,1/(宏观数据!$F$3:$UN$3<>""),COLUMN(宏观数据!$F$3:$UN$3))-COLUMN(宏观数据!$F$3))),"") -> 50 | I17: =IFERROR(LOOKUP(2,1/(宏观数据!$F$3:$UN$3<>"")/(宏观数据!$F$1:$UN$1<F17),宏观数据!$F$1:$UN$1),"") -> 46173
A18: 非制造业PMI | B18: 月度 | C18: M0048236 | D18: % | E18: =IFERROR(LOOKUP(9.99E+307,宏观数据!$F$8:$UN$8),"") -> 50.2 | F18: =IFERROR(LOOKUP(2,1/(宏观数据!$F$8:$UN$8<>""),宏观数据!$F$1:$UN$1),"") -> 46203 | G18: =IFERROR(E18-H18,"") -> 0.1 | H18: =IFERROR(LOOKUP(9.99E+307,OFFSET(宏观数据!$F$8,0,0,1,LOOKUP(2,1/(宏观数据!$F$8:$UN$8<>""),COLUMN(宏观数据!$F$8:$UN$8))-COLUMN(宏观数据!$F$8))),"") -> 50.1 | I18: =IFERROR(LOOKUP(2,1/(宏观数据!$F$8:$UN$8<>"")/(宏观数据!$F$1:$UN$1<F18),宏观数据!$F$1:$UN$1),"") -> 46173
A19: 工业增加值 | B19: 月度 | C19: M0000545 | D19: % | E19: =IFERROR(LOOKUP(9.99E+307,宏观数据!$F$20:$UN$20),"") -> 4.5 | F19: =IFERROR(LOOKUP(2,1/(宏观数据!$F$20:$UN$20<>""),宏观数据!$F$1:$UN$1),"") -> 46173 | G19: =IFERROR(E19-H19,"") -> 0.4 | H19: =IFERROR(LOOKUP(9.99E+307,OFFSET(宏观数据!$F$20,0,0,1,LOOKUP(2,1/(宏观数据!$F$20:$UN$20<>""),COLUMN(宏观数据!$F$20:$UN$20))-COLUMN(宏观数据!$F$20))),"") -> 4.1 | I19: =IFERROR(LOOKUP(2,1/(宏观数据!$F$20:$UN$20<>"")/(宏观数据!$F$1:$UN$1<F19),宏观数据!$F$1:$UN$1),"") -> 46142
A20: 出口 | B20: 月度 | C20: M0000607 | D20: % | E20: =IFERROR(LOOKUP(9.99E+307,宏观数据!$F$21:$UN$21),"") -> 19.4 | F20: =IFERROR(LOOKUP(2,1/(宏观数据!$F$21:$UN$21<>""),宏观数据!$F$1:$UN$1),"") -> 46173 | G20: =IFERROR(E20-H20,"") -> 5.4 | H20: =IFERROR(LOOKUP(9.99E+307,OFFSET(宏观数据!$F$21,0,0,1,LOOKUP(2,1/(宏观数据!$F$21:$UN$21<>""),COLUMN(宏观数据!$F$21:$UN$21))-COLUMN(宏观数据!$F$21))),"") -> 14 | I20: =IFERROR(LOOKUP(2,1/(宏观数据!$F$21:$UN$21<>"")/(宏观数据!$F$1:$UN$1<F20),宏观数据!$F$1:$UN$1),"") -> 46142
A21: PPI | B21: 月度 | C21: M0001227 | D21: % | E21: =IFERROR(LOOKUP(9.99E+307,宏观数据!$F$23:$UN$23),"") -> 3.9 | F21: =IFERROR(LOOKUP(2,1/(宏观数据!$F$23:$UN$23<>""),宏观数据!$F$1:$UN$1),"") -> 46173 | G21: =IFERROR(E21-H21,"") -> 1.1 | H21: =IFERROR(LOOKUP(9.99E+307,OFFSET(宏观数据!$F$23,0,0,1,LOOKUP(2,1/(宏观数据!$F$23:$UN$23<>""),COLUMN(宏观数据!$F$23:$UN$23))-COLUMN(宏观数据!$F$23))),"") -> 2.8 | I21: =IFERROR(LOOKUP(2,1/(宏观数据!$F$23:$UN$23<>"")/(宏观数据!$F$1:$UN$1<F21),宏观数据!$F$1:$UN$1),"") -> 46142
A22: CPI | B22: 月度 | C22: M0000612 | D22: % | E22: =IFERROR(LOOKUP(9.99E+307,宏观数据!$F$25:$UN$25),"") -> 1.2 | F22: =IFERROR(LOOKUP(2,1/(宏观数据!$F$25:$UN$25<>""),宏观数据!$F$1:$UN$1),"") -> 46173 | G22: =IFERROR(E22-H22,"") -> 0 | H22: =IFERROR(LOOKUP(9.99E+307,OFFSET(宏观数据!$F$25,0,0,1,LOOKUP(2,1/(宏观数据!$F$25:$UN$25<>""),COLUMN(宏观数据!$F$25:$UN$25))-COLUMN(宏观数据!$F$25))),"") -> 1.2 | I22: =IFERROR(LOOKUP(2,1/(宏观数据!$F$25:$UN$25<>"")/(宏观数据!$F$1:$UN$1<F22),宏观数据!$F$1:$UN$1),"") -> 46142
A23: 原材料购价 | B23: 月度 | C23: M0017134 | E23: =IFERROR(LOOKUP(9.99E+307,宏观数据!$F$107:$UN$107),"") -> 54.2 | F23: =IFERROR(LOOKUP(2,1/(宏观数据!$F$107:$UN$107<>""),宏观数据!$F$1:$UN$1),"") -> 46203 | G23: =IFERROR(E23-H23,"") -> -6.3 | H23: =IFERROR(LOOKUP(9.99E+307,OFFSET(宏观数据!$F$107,0,0,1,LOOKUP(2,1/(宏观数据!$F$107:$UN$107<>""),COLUMN(宏观数据!$F$107:$UN$107))-COLUMN(宏观数据!$F$107))),"") -> 60.5 | I23: =IFERROR(LOOKUP(2,1/(宏观数据!$F$107:$UN$107<>"")/(宏观数据!$F$1:$UN$1<F23),宏观数据!$F$1:$UN$1),"") -> 46173
A24: 中国:社会融资规模:当月值 | B24: 月度 | C24: M5206730 | D24: 亿元 | E24: =IFERROR(LOOKUP(9.99E+307,宏观数据!$F$114:$UN$114),"") -> 20264 | F24: =IFERROR(LOOKUP(2,1/(宏观数据!$F$114:$UN$114<>""),宏观数据!$F$1:$UN$1),"") -> 46173 | G24: =IFERROR(E24-H24,"") -> 14026 | H24: =IFERROR(LOOKUP(9.99E+307,OFFSET(宏观数据!$F$114,0,0,1,LOOKUP(2,1/(宏观数据!$F$114:$UN$114<>""),COLUMN(宏观数据!$F$114:$UN$114))-COLUMN(宏观数据!$F$114))),"") -> 6238 | I24: =IFERROR(LOOKUP(2,1/(宏观数据!$F$114:$UN$114<>"")/(宏观数据!$F$1:$UN$1<F24),宏观数据!$F$1:$UN$1),"") -> 46142
A25: 中国:社会融资规模:新增人民币贷款:当月值 | B25: 月度 | C25: M5206731 | D25: 亿元 | E25: =IFERROR(LOOKUP(9.99E+307,宏观数据!$F$115:$UN$115),"") -> 4965 | F25: =IFERROR(LOOKUP(2,1/(宏观数据!$F$115:$UN$115<>""),宏观数据!$F$1:$UN$1),"") -> 46173 | G25: =IFERROR(E25-H25,"") -> 8971 | H25: =IFERROR(LOOKUP(9.99E+307,OFFSET(宏观数据!$F$115,0,0,1,LOOKUP(2,1/(宏观数据!$F$115:$UN$115<>""),COLUMN(宏观数据!$F$115:$UN$115))-COLUMN(宏观数据!$F$115))),"") -> -4006 | I25: =IFERROR(LOOKUP(2,1/(宏观数据!$F$115:$UN$115<>"")/(宏观数据!$F$1:$UN$1<F25),宏观数据!$F$1:$UN$1),"") -> 46142
A26: 中国:社会融资规模:政府债券:当月值 | B26: 月度 | C26: M6179492 | D26: 亿元 | E26: =IFERROR(LOOKUP(9.99E+307,宏观数据!$F$116:$UN$116),"") -> 12236 | F26: =IFERROR(LOOKUP(2,1/(宏观数据!$F$116:$UN$116<>""),宏观数据!$F$1:$UN$1),"") -> 46173 | G26: =IFERROR(E26-H26,"") -> 3195 | H26: =IFERROR(LOOKUP(9.99E+307,OFFSET(宏观数据!$F$116,0,0,1,LOOKUP(2,1/(宏观数据!$F$116:$UN$116<>""),COLUMN(宏观数据!$F$116:$UN$116))-COLUMN(宏观数据!$F$116))),"") -> 9041 | I26: =IFERROR(LOOKUP(2,1/(宏观数据!$F$116:$UN$116<>"")/(宏观数据!$F$1:$UN$1<F26),宏观数据!$F$1:$UN$1),"") -> 46142
A27: 中国:社会融资规模:企业债券融资:当月值 | B27: 月度 | C27: M5206736 | D27: 亿元 | E27: =IFERROR(LOOKUP(9.99E+307,宏观数据!$F$117:$UN$117),"") -> 1680 | F27: =IFERROR(LOOKUP(2,1/(宏观数据!$F$117:$UN$117<>""),宏观数据!$F$1:$UN$1),"") -> 46173 | G27: =IFERROR(E27-H27,"") -> -2840 | H27: =IFERROR(LOOKUP(9.99E+307,OFFSET(宏观数据!$F$117,0,0,1,LOOKUP(2,1/(宏观数据!$F$117:$UN$117<>""),COLUMN(宏观数据!$F$117:$UN$117))-COLUMN(宏观数据!$F$117))),"") -> 4520 | I27: =IFERROR(LOOKUP(2,1/(宏观数据!$F$117:$UN$117<>"")/(宏观数据!$F$1:$UN$1<F27),宏观数据!$F$1:$UN$1),"") -> 46142
A28: 中国:社会融资规模:新增未贴现银行承兑汇票:当月值 | B28: 月度 | C28: M5206735 | D28: 亿元 | E28: =IFERROR(LOOKUP(9.99E+307,宏观数据!$F$118:$UN$118),"") -> -685 | F28: =IFERROR(LOOKUP(2,1/(宏观数据!$F$118:$UN$118<>""),宏观数据!$F$1:$UN$1),"") -> 46173 | G28: =IFERROR(E28-H28,"") -> 4599 | H28: =IFERROR(LOOKUP(9.99E+307,OFFSET(宏观数据!$F$118,0,0,1,LOOKUP(2,1/(宏观数据!$F$118:$UN$118<>""),COLUMN(宏观数据!$F$118:$UN$118))-COLUMN(宏观数据!$F$118))),"") -> -5284 | I28: =IFERROR(LOOKUP(2,1/(宏观数据!$F$118:$UN$118<>"")/(宏观数据!$F$1:$UN$1<F28),宏观数据!$F$1:$UN$1),"") -> 46142
A29: 中国:社会融资规模:新增外币贷款:当月值 | B29: 月度 | C29: M5206732 | D29: 亿元 | E29: =IFERROR(LOOKUP(9.99E+307,宏观数据!$F$119:$UN$119),"") -> 117 | F29: =IFERROR(LOOKUP(2,1/(宏观数据!$F$119:$UN$119<>""),宏观数据!$F$1:$UN$1),"") -> 46173 | G29: =IFERROR(E29-H29,"") -> -67 | H29: =IFERROR(LOOKUP(9.99E+307,OFFSET(宏观数据!$F$119,0,0,1,LOOKUP(2,1/(宏观数据!$F$119:$UN$119<>""),COLUMN(宏观数据!$F$119:$UN$119))-COLUMN(宏观数据!$F$119))),"") -> 184 | I29: =IFERROR(LOOKUP(2,1/(宏观数据!$F$119:$UN$119<>"")/(宏观数据!$F$1:$UN$1<F29),宏观数据!$F$1:$UN$1),"") -> 46142
A30: 中国:金融机构:新增人民币存款:财政存款:当月值 | B30: 月度 | C30: M0009945 | D30: 亿元 | E30: =IFERROR(LOOKUP(9.99E+307,宏观数据!$F$120:$UN$120),"") -> 7100 | F30: =IFERROR(LOOKUP(2,1/(宏观数据!$F$120:$UN$120<>""),宏观数据!$F$1:$UN$1),"") -> 46173 | G30: =IFERROR(E30-H30,"") -> -294 | H30: =IFERROR(LOOKUP(9.99E+307,OFFSET(宏观数据!$F$120,0,0,1,LOOKUP(2,1/(宏观数据!$F$120:$UN$120<>""),COLUMN(宏观数据!$F$120:$UN$120))-COLUMN(宏观数据!$F$120))),"") -> 7394 | I30: =IFERROR(LOOKUP(2,1/(宏观数据!$F$120:$UN$120<>"")/(宏观数据!$F$1:$UN$1<F30),宏观数据!$F$1:$UN$1),"") -> 46142
A31: 中国:房屋销售价格指数:二手住宅:70个大中城市:当月同比 | B31: 月度 | C31: S2707425 | D31: % | E31: =IFERROR(LOOKUP(9.99E+307,宏观数据!$F$121:$UN$121),"") -> -5.9 | F31: =IFERROR(LOOKUP(2,1/(宏观数据!$F$121:$UN$121<>""),宏观数据!$F$1:$UN$1),"") -> 46173 | G31: =IFERROR(E31-H31,"") -> 0.3 | H31: =IFERROR(LOOKUP(9.99E+307,OFFSET(宏观数据!$F$121,0,0,1,LOOKUP(2,1/(宏观数据!$F$121:$UN$121<>""),COLUMN(宏观数据!$F$121:$UN$121))-COLUMN(宏观数据!$F$121))),"") -> -6.2 | I31: =IFERROR(LOOKUP(2,1/(宏观数据!$F$121:$UN$121<>"")/(宏观数据!$F$1:$UN$1<F31),宏观数据!$F$1:$UN$1),"") -> 46142
A32: 中国:制造业PMI:新订单 | B32: 月度 | C32: M0017128 | D32: % | E32: =IFERROR(LOOKUP(9.99E+307,宏观数据!$F$122:$UN$122),"") -> 51.2 | F32: =IFERROR(LOOKUP(2,1/(宏观数据!$F$122:$UN$122<>""),宏观数据!$F$1:$UN$1),"") -> 46203 | G32: =IFERROR(E32-H32,"") -> 1.3 | H32: =IFERROR(LOOKUP(9.99E+307,OFFSET(宏观数据!$F$122,0,0,1,LOOKUP(2,1/(宏观数据!$F$122:$UN$122<>""),COLUMN(宏观数据!$F$122:$UN$122))-COLUMN(宏观数据!$F$122))),"") -> 49.9 | I32: =IFERROR(LOOKUP(2,1/(宏观数据!$F$122:$UN$122<>"")/(宏观数据!$F$1:$UN$1<F32),宏观数据!$F$1:$UN$1),"") -> 46173
A33: 中国:制造业PMI:生产 | B33: 月度 | C33: M0017127 | D33: % | E33: =IFERROR(LOOKUP(9.99E+307,宏观数据!$F$123:$UN$123),"") -> 51.4 | F33: =IFERROR(LOOKUP(2,1/(宏观数据!$F$123:$UN$123<>""),宏观数据!$F$1:$UN$1),"") -> 46203 | G33: =IFERROR(E33-H33,"") -> 0.2 | H33: =IFERROR(LOOKUP(9.99E+307,OFFSET(宏观数据!$F$123,0,0,1,LOOKUP(2,1/(宏观数据!$F$123:$UN$123<>""),COLUMN(宏观数据!$F$123:$UN$123))-COLUMN(宏观数据!$F$123))),"") -> 51.2 | I33: =IFERROR(LOOKUP(2,1/(宏观数据!$F$123:$UN$123<>"")/(宏观数据!$F$1:$UN$1<F33),宏观数据!$F$1:$UN$1),"") -> 46173
A34: 中国:营业收入利润率:规模以上工业企业:累计值 | B34: 月度 | C34: M5207655 | D34: % | E34: =IFERROR(LOOKUP(9.99E+307,宏观数据!$F$124:$UN$124),"") -> 5.56 | F34: =IFERROR(LOOKUP(2,1/(宏观数据!$F$124:$UN$124<>""),宏观数据!$F$1:$UN$1),"") -> 46173 | G34: =IFERROR(E34-H34,"") -> 0.13 | H34: =IFERROR(LOOKUP(9.99E+307,OFFSET(宏观数据!$F$124,0,0,1,LOOKUP(2,1/(宏观数据!$F$124:$UN$124<>""),COLUMN(宏观数据!$F$124:$UN$124))-COLUMN(宏观数据!$F$124))),"") -> 5.43 | I34: =IFERROR(LOOKUP(2,1/(宏观数据!$F$124:$UN$124<>"")/(宏观数据!$F$1:$UN$1<F34),宏观数据!$F$1:$UN$1),"") -> 46142
A35: 中国:利润总额:规模以上工业企业:累计同比 | B35: 月度 | C35: M0000557 | D35: % | E35: =IFERROR(LOOKUP(9.99E+307,宏观数据!$F$125:$UN$125),"") -> 18.8 | F35: =IFERROR(LOOKUP(2,1/(宏观数据!$F$125:$UN$125<>""),宏观数据!$F$1:$UN$1),"") -> 46173 | G35: =IFERROR(E35-H35,"") -> 0.6 | H35: =IFERROR(LOOKUP(9.99E+307,OFFSET(宏观数据!$F$125,0,0,1,LOOKUP(2,1/(宏观数据!$F$125:$UN$125<>""),COLUMN(宏观数据!$F$125:$UN$125))-COLUMN(宏观数据!$F$125))),"") -> 18.2 | I35: =IFERROR(LOOKUP(2,1/(宏观数据!$F$125:$UN$125<>"")/(宏观数据!$F$1:$UN$1<F35),宏观数据!$F$1:$UN$1),"") -> 46142
A36: 万得一致预测:中国:制造业PMI | B36: 月度 | C36: M0331594 | D36: % | E36: =IFERROR(LOOKUP(9.99E+307,宏观数据!$F$2:$UN$2),"") -> 50.08 | F36: =IFERROR(LOOKUP(2,1/(宏观数据!$F$2:$UN$2<>""),宏观数据!$F$1:$UN$1),"") -> 46234 | G36: =IFERROR(E36-H36,"") -> -0.12 | H36: =IFERROR(LOOKUP(9.99E+307,OFFSET(宏观数据!$F$2,0,0,1,LOOKUP(2,1/(宏观数据!$F$2:$UN$2<>""),COLUMN(宏观数据!$F$2:$UN$2))-COLUMN(宏观数据!$F$2))),"") -> 50.2 | I36: =IFERROR(LOOKUP(2,1/(宏观数据!$F$2:$UN$2<>"")/(宏观数据!$F$1:$UN$1<F36),宏观数据!$F$1:$UN$1),"") -> 46203
A37: 万得一致预测:中国:非制造业PMI | B37: 月度 | C37: A9541823 | D37: % | E37: =IFERROR(LOOKUP(9.99E+307,宏观数据!$F$4:$UN$4),"") -> 49.85 | F37: =IFERROR(LOOKUP(2,1/(宏观数据!$F$4:$UN$4<>""),宏观数据!$F$1:$UN$1),"") -> 46203 | G37: =IFERROR(E37-H37,"") -> -0.05 | H37: =IFERROR(LOOKUP(9.99E+307,OFFSET(宏观数据!$F$4,0,0,1,LOOKUP(2,1/(宏观数据!$F$4:$UN$4<>""),COLUMN(宏观数据!$F$4:$UN$4))-COLUMN(宏观数据!$F$4))),"") -> 49.9 | I37: =IFERROR(LOOKUP(2,1/(宏观数据!$F$4:$UN$4<>"")/(宏观数据!$F$1:$UN$1<F37),宏观数据!$F$1:$UN$1),"") -> 46142
A38: 中国:制造业PMI:新出口订单 | B38: 月度 | C38: M0017129 | D38: % | E38: =IFERROR(LOOKUP(9.99E+307,宏观数据!$F$7:$UN$7),"") -> 50.1 | F38: =IFERROR(LOOKUP(2,1/(宏观数据!$F$7:$UN$7<>""),宏观数据!$F$1:$UN$1),"") -> 46203 | G38: =IFERROR(E38-H38,"") -> 1.5 | H38: =IFERROR(LOOKUP(9.99E+307,OFFSET(宏观数据!$F$7,0,0,1,LOOKUP(2,1/(宏观数据!$F$7:$UN$7<>""),COLUMN(宏观数据!$F$7:$UN$7))-COLUMN(宏观数据!$F$7))),"") -> 48.6 | I38: =IFERROR(LOOKUP(2,1/(宏观数据!$F$7:$UN$7<>"")/(宏观数据!$F$1:$UN$1<F38),宏观数据!$F$1:$UN$1),"") -> 46173
A39: 万得一致预测:中国:社会消费品零售总额:当月同比 | B39: 月度 | C39: M0061679 | D39: % | E39: =IFERROR(LOOKUP(9.99E+307,宏观数据!$F$10:$UN$10),"") -> 1.5 | F39: =IFERROR(LOOKUP(2,1/(宏观数据!$F$10:$UN$10<>""),宏观数据!$F$1:$UN$1),"") -> 46234 | G39: =IFERROR(E39-H39,"") -> 1.37 | H39: =IFERROR(LOOKUP(9.99E+307,OFFSET(宏观数据!$F$10,0,0,1,LOOKUP(2,1/(宏观数据!$F$10:$UN$10<>""),COLUMN(宏观数据!$F$10:$UN$10))-COLUMN(宏观数据!$F$10))),"") -> 0.13 | I39: =IFERROR(LOOKUP(2,1/(宏观数据!$F$10:$UN$10<>"")/(宏观数据!$F$1:$UN$1<F39),宏观数据!$F$1:$UN$1),"") -> 46203
A40: 万得一致预测:中国:固定资产投资完成额:累计同比 | B40: 月度 | C40: M0061678 | D40: % | E40: =IFERROR(LOOKUP(9.99E+307,宏观数据!$F$11:$UN$11),"") -> -4.77 | F40: =IFERROR(LOOKUP(2,1/(宏观数据!$F$11:$UN$11<>""),宏观数据!$F$1:$UN$1),"") -> 46203 | G40: =IFERROR(E40-H40,"") -> -3.08 | H40: =IFERROR(LOOKUP(9.99E+307,OFFSET(宏观数据!$F$11,0,0,1,LOOKUP(2,1/(宏观数据!$F$11:$UN$11<>""),COLUMN(宏观数据!$F$11:$UN$11))-COLUMN(宏观数据!$F$11))),"") -> -1.69 | I40: =IFERROR(LOOKUP(2,1/(宏观数据!$F$11:$UN$11<>"")/(宏观数据!$F$1:$UN$1<F40),宏观数据!$F$1:$UN$1),"") -> 46173
...

Sheet 海外数据
B1: 频率 | C1: 代码 | D1: 单位 | E1: 当前数据 | F1: 数据日期 | G1: 变化 | H1: 上期数据 | I1: 上期日期 | J1: 趋势图
A2: 美国:国债收益率:2年 | B2: 日度 | C2: G0000887 | D2: % | E2: =IFERROR(LOOKUP(9.99E+307,宏观数据!$F$57:$UN$57),"") -> 4.14 | F2: =IFERROR(LOOKUP(2,1/(宏观数据!$F$57:$UN$57<>""),宏观数据!$F$1:$UN$1),"") -> 46205 | G2: =IFERROR(E2-H2,"") -> -0.03 | H2: =IFERROR(LOOKUP(9.99E+307,OFFSET(宏观数据!$F$57,0,0,1,LOOKUP(2,1/(宏观数据!$F$57:$UN$57<>""),COLUMN(宏观数据!$F$57:$UN$57))-COLUMN(宏观数据!$F$57))),"") -> 4.17 | I2: =IFERROR(LOOKUP(2,1/(宏观数据!$F$57:$UN$57<>"")/(宏观数据!$F$1:$UN$1<F2),宏观数据!$F$1:$UN$1),"") -> 46204
A3: 美国:国债收益率:10年 | B3: 日度 | C3: G0000891 | D3: % | E3: =IFERROR(LOOKUP(9.99E+307,宏观数据!$F$58:$UN$58),"") -> 4.49 | F3: =IFERROR(LOOKUP(2,1/(宏观数据!$F$58:$UN$58<>""),宏观数据!$F$1:$UN$1),"") -> 46205 | G3: =IFERROR(E3-H3,"") -> 0.01 | H3: =IFERROR(LOOKUP(9.99E+307,OFFSET(宏观数据!$F$58,0,0,1,LOOKUP(2,1/(宏观数据!$F$58:$UN$58<>""),COLUMN(宏观数据!$F$58:$UN$58))-COLUMN(宏观数据!$F$58))),"") -> 4.48 | I3: =IFERROR(LOOKUP(2,1/(宏观数据!$F$58:$UN$58<>"")/(宏观数据!$F$1:$UN$1<F3),宏观数据!$F$1:$UN$1),"") -> 46204
A4: 美元指数 | B4: 日度 | C4: M0000271 | D4: 点 | E4: =IFERROR(LOOKUP(9.99E+307,宏观数据!$F$59:$UN$59),"") -> 100.8749 | F4: =IFERROR(LOOKUP(2,1/(宏观数据!$F$59:$UN$59<>""),宏观数据!$F$1:$UN$1),"") -> 46206 | G4: =IFERROR(E4-H4,"") -> 0.0097 | H4: =IFERROR(LOOKUP(9.99E+307,OFFSET(宏观数据!$F$59,0,0,1,LOOKUP(2,1/(宏观数据!$F$59:$UN$59<>""),COLUMN(宏观数据!$F$59:$UN$59))-COLUMN(宏观数据!$F$59))),"") -> 100.8652 | I4: =IFERROR(LOOKUP(2,1/(宏观数据!$F$59:$UN$59<>"")/(宏观数据!$F$1:$UN$1<F4),宏观数据!$F$1:$UN$1),"") -> 46205
A5: 美国:CPI:非季调:同比 | B5: 月度 | C5: G0000027 | D5: % | E5: =IFERROR(LOOKUP(9.99E+307,宏观数据!$F$60:$UN$60),"") -> 4.2 | F5: =IFERROR(LOOKUP(2,1/(宏观数据!$F$60:$UN$60<>""),宏观数据!$F$1:$UN$1),"") -> 46173 | G5: =IFERROR(E5-H5,"") -> 0.4 | H5: =IFERROR(LOOKUP(9.99E+307,OFFSET(宏观数据!$F$60,0,0,1,LOOKUP(2,1/(宏观数据!$F$60:$UN$60<>""),COLUMN(宏观数据!$F$60:$UN$60))-COLUMN(宏观数据!$F$60))),"") -> 3.8 | I5: =IFERROR(LOOKUP(2,1/(宏观数据!$F$60:$UN$60<>"")/(宏观数据!$F$1:$UN$1<F5),宏观数据!$F$1:$UN$1),"") -> 46142
A6: 黄金ETF波动率指数 | B6: 日度 | C6: G1122642 | D6: 点 | E6: =IFERROR(LOOKUP(9.99E+307,宏观数据!$F$61:$UN$61),"") -> 26 | F6: =IFERROR(LOOKUP(2,1/(宏观数据!$F$61:$UN$61<>""),宏观数据!$F$1:$UN$1),"") -> 46205 | G6: =IFERROR(E6-H6,"") -> -1.12 | H6: =IFERROR(LOOKUP(9.99E+307,OFFSET(宏观数据!$F$61,0,0,1,LOOKUP(2,1/(宏观数据!$F$61:$UN$61<>""),COLUMN(宏观数据!$F$61:$UN$61))-COLUMN(宏观数据!$F$61))),"") -> 27.12 | I6: =IFERROR(LOOKUP(2,1/(宏观数据!$F$61:$UN$61<>"")/(宏观数据!$F$1:$UN$1<F6),宏观数据!$F$1:$UN$1),"") -> 46204
A7: CFETS:即期汇率:美元兑人民币 | B7: 日度 | C7: M0067855 | E7: =IFERROR(LOOKUP(9.99E+307,宏观数据!$F$62:$UN$62),"") -> 6.7804 | F7: =IFERROR(LOOKUP(2,1/(宏观数据!$F$62:$UN$62<>""),宏观数据!$F$1:$UN$1),"") -> 46206 | G7: =IFERROR(E7-H7,"") -> -0.0062 | H7: =IFERROR(LOOKUP(9.99E+307,OFFSET(宏观数据!$F$62,0,0,1,LOOKUP(2,1/(宏观数据!$F$62:$UN$62<>""),COLUMN(宏观数据!$F$62:$UN$62))-COLUMN(宏观数据!$F$62))),"") -> 6.7866 | I7: =IFERROR(LOOKUP(2,1/(宏观数据!$F$62:$UN$62<>"")/(宏观数据!$F$1:$UN$1<F7),宏观数据!$F$1:$UN$1),"") -> 46205
A8: 美国:PPI:最终需求:非季调:同比 | B8: 月度 | C8: G1138811 | D8: % | E8: =IFERROR(LOOKUP(9.99E+307,宏观数据!$F$63:$UN$63),"") -> 6.5 | F8: =IFERROR(LOOKUP(2,1/(宏观数据!$F$63:$UN$63<>""),宏观数据!$F$1:$UN$1),"") -> 46173 | G8: =IFERROR(E8-H8,"") -> 0.8 | H8: =IFERROR(LOOKUP(9.99E+307,OFFSET(宏观数据!$F$63,0,0,1,LOOKUP(2,1/(宏观数据!$F$63:$UN$63<>""),COLUMN(宏观数据!$F$63:$UN$63))-COLUMN(宏观数据!$F$63))),"") -> 5.7 | I8: =IFERROR(LOOKUP(2,1/(宏观数据!$F$63:$UN$63<>"")/(宏观数据!$F$1:$UN$1<F8),宏观数据!$F$1:$UN$1),"") -> 46142
A9: 美国:核心PCE:同比 | B9: 月度 | C9: G1100005 | D9: % | E9: =IFERROR(LOOKUP(9.99E+307,宏观数据!$F$64:$UN$64),"") -> 3.412 | F9: =IFERROR(LOOKUP(2,1/(宏观数据!$F$64:$UN$64<>""),宏观数据!$F$1:$UN$1),"") -> 46173 | G9: =IFERROR(E9-H9,"") -> 0.0933 | H9: =IFERROR(LOOKUP(9.99E+307,OFFSET(宏观数据!$F$64,0,0,1,LOOKUP(2,1/(宏观数据!$F$64:$UN$64<>""),COLUMN(宏观数据!$F$64:$UN$64))-COLUMN(宏观数据!$F$64))),"") -> 3.3187 | I9: =IFERROR(LOOKUP(2,1/(宏观数据!$F$64:$UN$64<>"")/(宏观数据!$F$1:$UN$1<F9),宏观数据!$F$1:$UN$1),"") -> 46142
A10: 美国:所有联储银行:资产:总资产 | B10: 月度 | C10: G1100075 | D10: 亿美元 | E10: =IFERROR(LOOKUP(9.99E+307,宏观数据!$F$65:$UN$65),"") -> 6724564 | F10: =IFERROR(LOOKUP(2,1/(宏观数据!$F$65:$UN$65<>""),宏观数据!$F$1:$UN$1),"") -> 46204 | G10: =IFERROR(E10-H10,"") -> -11081 | H10: =IFERROR(LOOKUP(9.99E+307,OFFSET(宏观数据!$F$65,0,0,1,LOOKUP(2,1/(宏观数据!$F$65:$UN$65<>""),COLUMN(宏观数据!$F$65:$UN$65))-COLUMN(宏观数据!$F$65))),"") -> 6735645 | I10: =IFERROR(LOOKUP(2,1/(宏观数据!$F$65:$UN$65<>"")/(宏观数据!$F$1:$UN$1<F10),宏观数据!$F$1:$UN$1),"") -> 46197
A11: 美国:国债未偿余额:适销国债 | B11: 月度 | C11: G1133075 | E11: =IFERROR(LOOKUP(9.99E+307,宏观数据!$F$66:$UN$66),"") -> 30909.941 | F11: =IFERROR(LOOKUP(2,1/(宏观数据!$F$66:$UN$66<>""),宏观数据!$F$1:$UN$1),"") -> 46173 | G11: =IFERROR(E11-H11,"") -> 236.82978 | H11: =IFERROR(LOOKUP(9.99E+307,OFFSET(宏观数据!$F$66,0,0,1,LOOKUP(2,1/(宏观数据!$F$66:$UN$66<>""),COLUMN(宏观数据!$F$66:$UN$66))-COLUMN(宏观数据!$F$66))),"") -> 30673.112 | I11: =IFERROR(LOOKUP(2,1/(宏观数据!$F$66:$UN$66<>"")/(宏观数据!$F$1:$UN$1<F11),宏观数据!$F$1:$UN$1),"") -> 46142
A12: 美国:有效联邦基金利率(EFFR) | B12: 日度 | C12: G0001699 | D12: % | E12: =IFERROR(LOOKUP(9.99E+307,宏观数据!$F$67:$UN$67),"") -> 3.63 | F12: =IFERROR(LOOKUP(2,1/(宏观数据!$F$67:$UN$67<>""),宏观数据!$F$1:$UN$1),"") -> 46204 | G12: =IFERROR(E12-H12,"") -> 0 | H12: =IFERROR(LOOKUP(9.99E+307,OFFSET(宏观数据!$F$67,0,0,1,LOOKUP(2,1/(宏观数据!$F$67:$UN$67<>""),COLUMN(宏观数据!$F$67:$UN$67))-COLUMN(宏观数据!$F$67))),"") -> 3.63 | I12: =IFERROR(LOOKUP(2,1/(宏观数据!$F$67:$UN$67<>"")/(宏观数据!$F$1:$UN$1<F12),宏观数据!$F$1:$UN$1),"") -> 46203
A13: 美国担保隔夜融资利率(SOFR) | B13: 周度 | C13: M0341926 | D13: % | E13: =IFERROR(LOOKUP(9.99E+307,宏观数据!$F$68:$UN$68),"") -> 3.66 | F13: =IFERROR(LOOKUP(2,1/(宏观数据!$F$68:$UN$68<>""),宏观数据!$F$1:$UN$1),"") -> 46204 | G13: =IFERROR(E13-H13,"") -> -0.02 | H13: =IFERROR(LOOKUP(9.99E+307,OFFSET(宏观数据!$F$68,0,0,1,LOOKUP(2,1/(宏观数据!$F$68:$UN$68<>""),COLUMN(宏观数据!$F$68:$UN$68))-COLUMN(宏观数据!$F$68))),"") -> 3.68 | I13: =IFERROR(LOOKUP(2,1/(宏观数据!$F$68:$UN$68<>"")/(宏观数据!$F$1:$UN$1<F13),宏观数据!$F$1:$UN$1),"") -> 46203
A14: 美国:ISM:制造业PMI | B14: 月度 | C14: G0002323 | D14: % | E14: =IFERROR(LOOKUP(9.99E+307,宏观数据!$F$69:$UN$69),"") -> 53.3 | F14: =IFERROR(LOOKUP(2,1/(宏观数据!$F$69:$UN$69<>""),宏观数据!$F$1:$UN$1),"") -> 46203 | G14: =IFERROR(E14-H14,"") -> -0.7 | H14: =IFERROR(LOOKUP(9.99E+307,OFFSET(宏观数据!$F$69,0,0,1,LOOKUP(2,1/(宏观数据!$F$69:$UN$69<>""),COLUMN(宏观数据!$F$69:$UN$69))-COLUMN(宏观数据!$F$69))),"") -> 54 | I14: =IFERROR(LOOKUP(2,1/(宏观数据!$F$69:$UN$69<>"")/(宏观数据!$F$1:$UN$1<F14),宏观数据!$F$1:$UN$1),"") -> 46173
A15: 美国:零售和食品服务销售额:季调:环比 | B15: 月度 | C15: G1109265 | D15: % | E15: =IFERROR(LOOKUP(9.99E+307,宏观数据!$F$70:$UN$70),"") -> 0.880936 | F15: =IFERROR(LOOKUP(2,1/(宏观数据!$F$70:$UN$70<>""),宏观数据!$F$1:$UN$1),"") -> 46173 | G15: =IFERROR(E15-H15,"") -> 0.480015 | H15: =IFERROR(LOOKUP(9.99E+307,OFFSET(宏观数据!$F$70,0,0,1,LOOKUP(2,1/(宏观数据!$F$70:$UN$70<>""),COLUMN(宏观数据!$F$70:$UN$70))-COLUMN(宏观数据!$F$70))),"") -> 0.400921 | I15: =IFERROR(LOOKUP(2,1/(宏观数据!$F$70:$UN$70<>"")/(宏观数据!$F$1:$UN$1<F15),宏观数据!$F$1:$UN$1),"") -> 46142
A16: 美国:密歇根大学消费者信心指数 | B16: 月度 | C16: G0002325 | D16: 点 | E16: =IFERROR(LOOKUP(9.99E+307,宏观数据!$F$71:$UN$71),"") -> 49.5 | F16: =IFERROR(LOOKUP(2,1/(宏观数据!$F$71:$UN$71<>""),宏观数据!$F$1:$UN$1),"") -> 46203 | G16: =IFERROR(E16-H16,"") -> 4.7 | H16: =IFERROR(LOOKUP(9.99E+307,OFFSET(宏观数据!$F$71,0,0,1,LOOKUP(2,1/(宏观数据!$F$71:$UN$71<>""),COLUMN(宏观数据!$F$71:$UN$71))-COLUMN(宏观数据!$F$71))),"") -> 44.8 | I16: =IFERROR(LOOKUP(2,1/(宏观数据!$F$71:$UN$71<>"")/(宏观数据!$F$1:$UN$1<F16),宏观数据!$F$1:$UN$1),"") -> 46173
A17: 美国:新建住房销量:非季调 | B17: 月度 | C17: G0003645 | E17: =IFERROR(LOOKUP(9.99E+307,宏观数据!$F$72:$UN$72),"") -> 51 | F17: =IFERROR(LOOKUP(2,1/(宏观数据!$F$72:$UN$72<>""),宏观数据!$F$1:$UN$1),"") -> 46173 | G17: =IFERROR(E17-H17,"") -> -8 | H17: =IFERROR(LOOKUP(9.99E+307,OFFSET(宏观数据!$F$72,0,0,1,LOOKUP(2,1/(宏观数据!$F$72:$UN$72<>""),COLUMN(宏观数据!$F$72:$UN$72))-COLUMN(宏观数据!$F$72))),"") -> 59 | I17: =IFERROR(LOOKUP(2,1/(宏观数据!$F$72:$UN$72<>"")/(宏观数据!$F$1:$UN$1<F17),宏观数据!$F$1:$UN$1),"") -> 46142
A18: 美国:建造支出:非季调 | B18: 月度 | C18: G0003478 | E18: =IFERROR(LOOKUP(9.99E+307,宏观数据!$F$73:$UN$73),"") -> 191951 | F18: =IFERROR(LOOKUP(2,1/(宏观数据!$F$73:$UN$73<>""),宏观数据!$F$1:$UN$1),"") -> 46173 | G18: =IFERROR(E18-H18,"") -> 9942 | H18: =IFERROR(LOOKUP(9.99E+307,OFFSET(宏观数据!$F$73,0,0,1,LOOKUP(2,1/(宏观数据!$F$73:$UN$73<>""),COLUMN(宏观数据!$F$73:$UN$73))-COLUMN(宏观数据!$F$73))),"") -> 182009 | I18: =IFERROR(LOOKUP(2,1/(宏观数据!$F$73:$UN$73<>"")/(宏观数据!$F$1:$UN$1<F18),宏观数据!$F$1:$UN$1),"") -> 46142
A19: 美国:ISM:服务业PMI:新订单 | B19: 月度 | C19: G0008356 | D19: % | E19: =IFERROR(LOOKUP(9.99E+307,宏观数据!$F$74:$UN$74),"") -> 57.3 | F19: =IFERROR(LOOKUP(2,1/(宏观数据!$F$74:$UN$74<>""),宏观数据!$F$1:$UN$1),"") -> 46173 | G19: =IFERROR(E19-H19,"") -> 3.8 | H19: =IFERROR(LOOKUP(9.99E+307,OFFSET(宏观数据!$F$74,0,0,1,LOOKUP(2,1/(宏观数据!$F$74:$UN$74<>""),COLUMN(宏观数据!$F$74:$UN$74))-COLUMN(宏观数据!$F$74))),"") -> 53.5 | I19: =IFERROR(LOOKUP(2,1/(宏观数据!$F$74:$UN$74<>"")/(宏观数据!$F$1:$UN$1<F19),宏观数据!$F$1:$UN$1),"") -> 46142
A20: 美国:出口金额:商品和服务贸易:季调:同比 | B20: 月度 | C20: G1100352 | D20: % | E20: =IFERROR(LOOKUP(9.99E+307,宏观数据!$F$75:$UN$75),"") -> 12.56 | F20: =IFERROR(LOOKUP(2,1/(宏观数据!$F$75:$UN$75<>""),宏观数据!$F$1:$UN$1),"") -> 46142 | G20: =IFERROR(E20-H20,"") -> 0.06 | H20: =IFERROR(LOOKUP(9.99E+307,OFFSET(宏观数据!$F$75,0,0,1,LOOKUP(2,1/(宏观数据!$F$75:$UN$75<>""),COLUMN(宏观数据!$F$75:$UN$75))-COLUMN(宏观数据!$F$75))),"") -> 12.5 | I20: =IFERROR(LOOKUP(2,1/(宏观数据!$F$75:$UN$75<>"")/(宏观数据!$F$1:$UN$1<F20),宏观数据!$F$1:$UN$1),"") -> 46112
A21: 美国:失业率:季调 | B21: 月度 | C21: G0000067 | D21: % | E21: =IFERROR(LOOKUP(9.99E+307,宏观数据!$F$76:$UN$76),"") -> 4.2 | F21: =IFERROR(LOOKUP(2,1/(宏观数据!$F$76:$UN$76<>""),宏观数据!$F$1:$UN$1),"") -> 46203 | G21: =IFERROR(E21-H21,"") -> -0.1 | H21: =IFERROR(LOOKUP(9.99E+307,OFFSET(宏观数据!$F$76,0,0,1,LOOKUP(2,1/(宏观数据!$F$76:$UN$76<>""),COLUMN(宏观数据!$F$76:$UN$76))-COLUMN(宏观数据!$F$76))),"") -> 4.3 | I21: =IFERROR(LOOKUP(2,1/(宏观数据!$F$76:$UN$76<>"")/(宏观数据!$F$1:$UN$1<F21),宏观数据!$F$1:$UN$1),"") -> 46173
A22: 美国:新增ADP就业人数:季调 | B22: 月度 | C22: L7714005 | E22: =IFERROR(LOOKUP(9.99E+307,宏观数据!$F$77:$UN$77),"") -> 98000 | F22: =IFERROR(LOOKUP(2,1/(宏观数据!$F$77:$UN$77<>""),宏观数据!$F$1:$UN$1),"") -> 46203 | G22: =IFERROR(E22-H22,"") -> -24000 | H22: =IFERROR(LOOKUP(9.99E+307,OFFSET(宏观数据!$F$77,0,0,1,LOOKUP(2,1/(宏观数据!$F$77:$UN$77<>""),COLUMN(宏观数据!$F$77:$UN$77))-COLUMN(宏观数据!$F$77))),"") -> 122000 | I22: =IFERROR(LOOKUP(2,1/(宏观数据!$F$77:$UN$77<>"")/(宏观数据!$F$1:$UN$1<F22),宏观数据!$F$1:$UN$1),"") -> 46173
A23: 美国:财政赤字(盈余为负):同比 | B23: 月度 | C23: G1100346 | D23: % | E23: =IFERROR(LOOKUP(9.99E+307,宏观数据!$F$78:$UN$78),"") -> -7.29 | F23: =IFERROR(LOOKUP(2,1/(宏观数据!$F$78:$UN$78<>""),宏观数据!$F$1:$UN$1),"") -> 46173 | G23: =IFERROR(E23-H23,"") -> -24.08 | H23: =IFERROR(LOOKUP(9.99E+307,OFFSET(宏观数据!$F$78,0,0,1,LOOKUP(2,1/(宏观数据!$F$78:$UN$78<>""),COLUMN(宏观数据!$F$78:$UN$78))-COLUMN(宏观数据!$F$78))),"") -> 16.79 | I23: =IFERROR(LOOKUP(2,1/(宏观数据!$F$78:$UN$78<>"")/(宏观数据!$F$1:$UN$1<F23),宏观数据!$F$1:$UN$1),"") -> 46142
A24: 美国:ISM:服务业PMI | B24: 月度 | C24: G0002324 | D24: % | E24: =IFERROR(LOOKUP(9.99E+307,宏观数据!$F$87:$UN$87),"") -> 54.5 | F24: =IFERROR(LOOKUP(2,1/(宏观数据!$F$87:$UN$87<>""),宏观数据!$F$1:$UN$1),"") -> 46173 | G24: =IFERROR(E24-H24,"") -> 0.9 | H24: =IFERROR(LOOKUP(9.99E+307,OFFSET(宏观数据!$F$87,0,0,1,LOOKUP(2,1/(宏观数据!$F$87:$UN$87<>""),COLUMN(宏观数据!$F$87:$UN$87))-COLUMN(宏观数据!$F$87))),"") -> 53.6 | I24: =IFERROR(LOOKUP(2,1/(宏观数据!$F$87:$UN$87<>"")/(宏观数据!$F$1:$UN$1<F24),宏观数据!$F$1:$UN$1),"") -> 46142
A25: 美国:所有商业银行:资产:银行信贷:季调 | B25: 月度 | C25: G1109077 | D25: 亿美元 | E25: =IFERROR(LOOKUP(9.99E+307,宏观数据!$F$88:$UN$88),"") -> 19643284 | F25: =IFERROR(LOOKUP(2,1/(宏观数据!$F$88:$UN$88<>""),宏观数据!$F$1:$UN$1),"") -> 46197 | G25: =IFERROR(E25-H25,"") -> 22441.4 | H25: =IFERROR(LOOKUP(9.99E+307,OFFSET(宏观数据!$F$88,0,0,1,LOOKUP(2,1/(宏观数据!$F$88:$UN$88<>""),COLUMN(宏观数据!$F$88:$UN$88))-COLUMN(宏观数据!$F$88))),"") -> 19620843 | I25: =IFERROR(LOOKUP(2,1/(宏观数据!$F$88:$UN$88<>"")/(宏观数据!$F$1:$UN$1<F25),宏观数据!$F$1:$UN$1),"") -> 46190
A26: 美国:存款机构:负债:除储备金外的联储银行存款:美国财政部一般账户 | B26: 月度 | C26: G1100038 | D26: 亿美元 | E26: =IFERROR(LOOKUP(9.99E+307,宏观数据!$F$89:$UN$89),"") -> 807359 | F26: =IFERROR(LOOKUP(2,1/(宏观数据!$F$89:$UN$89<>""),宏观数据!$F$1:$UN$1),"") -> 46204 | G26: =IFERROR(E26-H26,"") -> -94486 | H26: =IFERROR(LOOKUP(9.99E+307,OFFSET(宏观数据!$F$89,0,0,1,LOOKUP(2,1/(宏观数据!$F$89:$UN$89<>""),COLUMN(宏观数据!$F$89:$UN$89))-COLUMN(宏观数据!$F$89))),"") -> 901845 | I26: =IFERROR(LOOKUP(2,1/(宏观数据!$F$89:$UN$89<>"")/(宏观数据!$F$1:$UN$1<F26),宏观数据!$F$1:$UN$1),"") -> 46197
A27: 标准普尔500波动率指数(VIX) | B27: 日度 | C27: G0003892 | D27: 点 | E27: =IFERROR(LOOKUP(9.99E+307,宏观数据!$F$90:$UN$90),"") -> 15.81 | F27: =IFERROR(LOOKUP(2,1/(宏观数据!$F$90:$UN$90<>""),宏观数据!$F$1:$UN$1),"") -> 46206 | G27: =IFERROR(E27-H27,"") -> -0.34 | H27: =IFERROR(LOOKUP(9.99E+307,OFFSET(宏观数据!$F$90,0,0,1,LOOKUP(2,1/(宏观数据!$F$90:$UN$90<>""),COLUMN(宏观数据!$F$90:$UN$90))-COLUMN(宏观数据!$F$90))),"") -> 16.15 | I27: =IFERROR(LOOKUP(2,1/(宏观数据!$F$90:$UN$90<>"")/(宏观数据!$F$1:$UN$1<F27),宏观数据!$F$1:$UN$1),"") -> 46205
A28: 市盈率:标准普尔500指数 | B28: 月度 | C28: G0011297 | D28: 点 | E28: =IFERROR(LOOKUP(9.99E+307,宏观数据!$F$91:$UN$91),"") -> 28.3122 | F28: =IFERROR(LOOKUP(2,1/(宏观数据!$F$91:$UN$91<>""),宏观数据!$F$1:$UN$1),"") -> 46208 | G28: =IFERROR(E28-H28,"") -> 0 | H28: =IFERROR(LOOKUP(9.99E+307,OFFSET(宏观数据!$F$91,0,0,1,LOOKUP(2,1/(宏观数据!$F$91:$UN$91<>""),COLUMN(宏观数据!$F$91:$UN$91))-COLUMN(宏观数据!$F$91))),"") -> 28.3122 | I28: =IFERROR(LOOKUP(2,1/(宏观数据!$F$91:$UN$91<>"")/(宏观数据!$F$1:$UN$1<F28),宏观数据!$F$1:$UN$1),"") -> 46207
A29: 美国:国债拍卖竞拍倍数:2年 | B29: 不定期 | C29: G1130724 | E29: =IFERROR(LOOKUP(9.99E+307,宏观数据!$F$92:$UN$92),"") -> 2.4295 | F29: =IFERROR(LOOKUP(2,1/(宏观数据!$F$92:$UN$92<>""),宏观数据!$F$1:$UN$1),"") -> 46196 | G29: =IFERROR(E29-H29,"") -> 0.0015 | H29: =IFERROR(LOOKUP(9.99E+307,OFFSET(宏观数据!$F$92,0,0,1,LOOKUP(2,1/(宏观数据!$F$92:$UN$92<>""),COLUMN(宏观数据!$F$92:$UN$92))-COLUMN(宏观数据!$F$92))),"") -> 2.428 | I29: =IFERROR(LOOKUP(2,1/(宏观数据!$F$92:$UN$92<>"")/(宏观数据!$F$1:$UN$1<F29),宏观数据!$F$1:$UN$1),"") -> 46168
A30: 美国:国债拍卖竞拍倍数:5年 | B30: 不定期 | C30: G1130736 | E30: =IFERROR(LOOKUP(9.99E+307,宏观数据!$F$93:$UN$93),"") -> 2.1751 | F30: =IFERROR(LOOKUP(2,1/(宏观数据!$F$93:$UN$93<>""),宏观数据!$F$1:$UN$1),"") -> 46197 | G30: =IFERROR(E30-H30,"") -> 0.0071 | H30: =IFERROR(LOOKUP(9.99E+307,OFFSET(宏观数据!$F$93,0,0,1,LOOKUP(2,1/(宏观数据!$F$93:$UN$93<>""),COLUMN(宏观数据!$F$93:$UN$93))-COLUMN(宏观数据!$F$93))),"") -> 2.168 | I30: =IFERROR(LOOKUP(2,1/(宏观数据!$F$93:$UN$93<>"")/(宏观数据!$F$1:$UN$1<F30),宏观数据!$F$1:$UN$1),"") -> 46169
A31: 美国:国债拍卖竞拍倍数:10年 | B31: 不定期 | C31: G1130748 | E31: =IFERROR(LOOKUP(9.99E+307,宏观数据!$F$94:$UN$94),"") -> 2.5652 | F31: =IFERROR(LOOKUP(2,1/(宏观数据!$F$94:$UN$94<>""),宏观数据!$F$1:$UN$1),"") -> 46183 | G31: =IFERROR(E31-H31,"") -> 0.4321 | H31: =IFERROR(LOOKUP(9.99E+307,OFFSET(宏观数据!$F$94,0,0,1,LOOKUP(2,1/(宏观数据!$F$94:$UN$94<>""),COLUMN(宏观数据!$F$94:$UN$94))-COLUMN(宏观数据!$F$94))),"") -> 2.1331 | I31: =IFERROR(LOOKUP(2,1/(宏观数据!$F$94:$UN$94<>"")/(宏观数据!$F$1:$UN$1<F31),宏观数据!$F$1:$UN$1),"") -> 46154
A32: 美国:国债拍卖竞拍倍数:30年 | B32: 不定期 | C32: G1130766 | E32: =IFERROR(LOOKUP(9.99E+307,宏观数据!$F$95:$UN$95),"") -> 2.3282 | F32: =IFERROR(LOOKUP(2,1/(宏观数据!$F$95:$UN$95<>""),宏观数据!$F$1:$UN$1),"") -> 46184 | G32: =IFERROR(E32-H32,"") -> 0.2755 | H32: =IFERROR(LOOKUP(9.99E+307,OFFSET(宏观数据!$F$95,0,0,1,LOOKUP(2,1/(宏观数据!$F$95:$UN$95<>""),COLUMN(宏观数据!$F$95:$UN$95))-COLUMN(宏观数据!$F$95))),"") -> 2.0527 | I32: =IFERROR(LOOKUP(2,1/(宏观数据!$F$95:$UN$95<>"")/(宏观数据!$F$1:$UN$1<F32),宏观数据!$F$1:$UN$1),"") -> 46155
A33: 美国:当周初次申请失业金人数:非季调 | B33: 周度 | C33: V7993283 | E33: =IFERROR(LOOKUP(9.99E+307,宏观数据!$F$96:$UN$96),"") -> 213550 | F33: =IFERROR(LOOKUP(2,1/(宏观数据!$F$96:$UN$96<>""),宏观数据!$F$1:$UN$1),"") -> 46200 | G33: =IFERROR(E33-H33,"") -> 5545 | H33: =IFERROR(LOOKUP(9.99E+307,OFFSET(宏观数据!$F$96,0,0,1,LOOKUP(2,1/(宏观数据!$F$96:$UN$96<>""),COLUMN(宏观数据!$F$96:$UN$96))-COLUMN(宏观数据!$F$96))),"") -> 208005 | I33: =IFERROR(LOOKUP(2,1/(宏观数据!$F$96:$UN$96<>"")/(宏观数据!$F$1:$UN$1<F33),宏观数据!$F$1:$UN$1),"") -> 46193
A34: 美国:密歇根大学:通胀率预期:1年 | B34: 月度 | C34: P9918147 | E34: =IFERROR(LOOKUP(9.99E+307,宏观数据!$F$97:$UN$97),"") -> 4.6 | F34: =IFERROR(LOOKUP(2,1/(宏观数据!$F$97:$UN$97<>""),宏观数据!$F$1:$UN$1),"") -> 46203 | G34: =IFERROR(E34-H34,"") -> -0.2 | H34: =IFERROR(LOOKUP(9.99E+307,OFFSET(宏观数据!$F$97,0,0,1,LOOKUP(2,1/(宏观数据!$F$97:$UN$97<>""),COLUMN(宏观数据!$F$97:$UN$97))-COLUMN(宏观数据!$F$97))),"") -> 4.8 | I34: =IFERROR(LOOKUP(2,1/(宏观数据!$F$97:$UN$97<>"")/(宏观数据!$F$1:$UN$1<F34),宏观数据!$F$1:$UN$1),"") -> 46173
